Workbook

Sheet 最後總成績算分
A1: 名字 | B1: 學號 | C1: 分組 | D1: Cybersecurity news presentation | E1: Malware analysis | F1: Machine learning in malware analysis | G1: Project Proposal | H1: Project Proposal Form | I1: Red team practice | J1: Red team practice Form | K1: Paper presentation | L1: Week 12 - Paper Form | M1: Week 13 - Paper Form | N1: Week 14 - Paper Form | O1: Final Project | P1: Final Project Form 1 | Q1: Final Project Form 2 | R1: Cybersec 2026 心得 | S1: LLM 回答 | T1: 缺席 | U1: 總分 | V1: 總分(無條件進位) | W1: 等第
D2: 0.1 | E2: 0.1 | F2: 0.1 | G2: 0.04 | H2: 0.01 | I2: 0.08 | J2: 0.02 | K2: 0.15 | L2: 0.05 | M2: 0.05 | N2: 0.05 | O2: 0.2 | P2: 0.025 | Q2: 0.025 | R2: 一次0.25 | S2: 一次0.25
A3: 黃文良 | B3: B11107152 | C3: ANTSLAB | D3: 86 | E3: 94 | F3: 100 | G3: 95 | H3: 86 | I3: 93 | J3: {=_xlfn.XLOOKUP($A3, 'Camping Simulation'!$B:$B, 'Camping Simulation'!$K:$K, "X")} -> 87 | K3: 94 | L3: 89 | M3: 89 | N3: 89 | O3: 95 | P3: 86 | Q3: 0 | R3: 1 | T3: 1 | U3: =D3*$D$2+E3*$E$2+F3*$F$2+G3*$G$2+H3*$H$2+I3*$I$2+J3*$J$2+K3*$K$2+L3*$L$2+M3*$M$2+N3*$N$2+O3*$O$2+P3*$P$2+Q3*$Q$2-5*T3+R3*0.25+S3*0.25 -> 85.69 | V3: =ROUNDUP(U3,0) -> 86 | W3: =IFS(V3>=90, "A+", V3>=85, "A", V3>=80, "A-", V3>=77, "B+", V3>=73, "B", V3>=70, "B-", TRUE, "") -> A
A4: 胡承學 | B4: B11107153 | C4: ANTSLAB | D4: 86 | E4: 94 | F4: 0 | G4: 95 | H4: 0 | I4: 93 | J4: {=_xlfn.XLOOKUP($A4, 'Camping Simulation'!$B:$B, 'Camping Simulation'!$K:$K, "X")} -> 90 | K4: 94 | L4: 90 | M4: 90 | N4: 90 | O4: 95 | P4: 88 | Q4: 89 | U4: =D4*$D$2+E4*$E$2+F4*$F$2+G4*$G$2+H4*$H$2+I4*$I$2+J4*$J$2+K4*$K$2+L4*$L$2+M4*$M$2+N4*$N$2+O4*$O$2+P4*$P$2+Q4*$Q$2-5*T4+R4*0.25+S4*0.25 -> 82.065 | V4: =ROUNDUP(U4,0) -> 83 | W4: =IFS(V4>=90, "A+", V4>=85, "A", V4>=80, "A-", V4>=77, "B+", V4>=73, "B", V4>=70, "B-", TRUE, "") -> A-
A5: 吳永保 | B5: M11407005 | C5: ANTSLAB | D5: 86 | E5: 94 | F5: 100 | G5: 95 | H5: 88 | I5: 93 | J5: {=_xlfn.XLOOKUP($A5, 'Camping Simulation'!$B:$B, 'Camping Simulation'!$K:$K, "X")} -> 89 | K5: 94 | L5: 92 | M5: 90 | N5: 92 | O5: 95 | P5: 89 | Q5: 92 | U5: =D5*$D$2+E5*$E$2+F5*$F$2+G5*$G$2+H5*$H$2+I5*$I$2+J5*$J$2+K5*$K$2+L5*$L$2+M5*$M$2+N5*$N$2+O5*$O$2+P5*$P$2+Q5*$Q$2-5*T5+R5*0.25+S5*0.25 -> 93.225 | V5: =ROUNDUP(U5,0) -> 94 | W5: =IFS(V5>=90, "A+", V5>=85, "A", V5>=80, "A-", V5>=77, "B+", V5>=73, "B", V5>=70, "B-", TRUE, "") -> A+
A6: 楊晴安 | B6: M11407507 | C6: ANTSLAB | D6: 86 | E6: 94 | F6: 100 | G6: 95 | H6: 89 | I6: 93 | J6: {=_xlfn.XLOOKUP($A6, 'Camping Simulation'!$B:$B, 'Camping Simulation'!$K:$K, "X")} -> 92 | K6: 94 | L6: 93 | M6: 91 | N6: 92 | O6: 95 | P6: 90 | Q6: 93 | R6: 1 | U6: =D6*$D$2+E6*$E$2+F6*$F$2+G6*$G$2+H6*$H$2+I6*$I$2+J6*$J$2+K6*$K$2+L6*$L$2+M6*$M$2+N6*$N$2+O6*$O$2+P6*$P$2+Q6*$Q$2-5*T6+R6*0.25+S6*0.25 -> 93.695 | V6: =ROUNDUP(U6,0) -> 94 | W6: =IFS(V6>=90, "A+", V6>=85, "A", V6>=80, "A-", V6>=77, "B+", V6>=73, "B", V6>=70, "B-", TRUE, "") -> A+
A7: 洪粲鈞 | B7: M11407519 | C7: ANTSLAB | D7: 86 | E7: 94 | F7: 100 | G7: 95 | H7: 93 | I7: 93 | J7: {=_xlfn.XLOOKUP($A7, 'Camping Simulation'!$B:$B, 'Camping Simulation'!$K:$K, "X")} -> 89 | K7: 94 | L7: 90 | M7: 92 | N7: 91 | O7: 95 | P7: 90 | Q7: 90 | R7: 1 | U7: =D7*$D$2+E7*$E$2+F7*$F$2+G7*$G$2+H7*$H$2+I7*$I$2+J7*$J$2+K7*$K$2+L7*$L$2+M7*$M$2+N7*$N$2+O7*$O$2+P7*$P$2+Q7*$Q$2-5*T7+R7*0.25+S7*0.25 -> 93.45 | V7: =ROUNDUP(U7,0) -> 94 | W7: =IFS(V7>=90, "A+", V7>=85, "A", V7>=80, "A-", V7>=77, "B+", V7>=73, "B", V7>=70, "B-", TRUE, "") -> A+
A8: 張惟凱 | B8: M11407522 | C8: ANTSLAB | D8: 86 | E8: 94 | F8: 100 | G8: 95 | H8: 92 | I8: 93 | J8: {=_xlfn.XLOOKUP($A8, 'Camping Simulation'!$B:$B, 'Camping Simulation'!$K:$K, "X")} -> 92 | K8: 94 | L8: 92 | M8: 91 | N8: 93 | O8: 95 | P8: 94 | Q8: 93 | R8: 1 | U8: =D8*$D$2+E8*$E$2+F8*$F$2+G8*$G$2+H8*$H$2+I8*$I$2+J8*$J$2+K8*$K$2+L8*$L$2+M8*$M$2+N8*$N$2+O8*$O$2+P8*$P$2+Q8*$Q$2-5*T8+R8*0.25+S8*0.25 -> 93.825 | V8: =ROUNDUP(U8,0) -> 94 | W8: =IFS(V8>=90, "A+", V8>=85, "A", V8>=80, "A-", V8>=77, "B+", V8>=73, "B", V8>=70, "B-", TRUE, "") -> A+
A9: SU YADANA WIN | B9: d11415809 | C9: BENI | D9: 90 | E9: 84 | F9: 100 | G9: 95 | H9: 88 | I9: 91 | J9: 0 | K9: 85 | L9: 94 | M9: 91 | N9: 90 | O9: 95 | P9: 95 | Q9: 95 | R9: 1 | U9: =D9*$D$2+E9*$E$2+F9*$F$2+G9*$G$2+H9*$H$2+I9*$I$2+J9*$J$2+K9*$K$2+L9*$L$2+M9*$M$2+N9*$N$2+O9*$O$2+P9*$P$2+Q9*$Q$2-5*T9+R9*0.25+S9*0.25 -> 89.86 | V9: =ROUNDUP(U9,0) -> 90 | W9: =IFS(V9>=90, "A+", V9>=85, "A", V9>=80, "A-", V9>=77, "B+", V9>=73, "B", V9>=70, "B-", TRUE, "") -> A+
A10: Jules GIRARD | B10: e11415022 | C10: BENI | D10: 90 | E10: 84 | F10: 0 | G10: 95 | H10: 90 | I10: 91 | J10: {=_xlfn.XLOOKUP($A10, 'Camping Simulation'!$B:$B, 'Camping Simulation'!$K:$K, "X")} -> 89 | K10: 85 | L10: 91 | M10: 90 | N10: 91 | O10: 95 | P10: 92 | Q10: 93 | U10: =D10*$D$2+E10*$E$2+F10*$F$2+G10*$G$2+H10*$H$2+I10*$I$2+J10*$J$2+K10*$K$2+L10*$L$2+M10*$M$2+N10*$N$2+O10*$O$2+P10*$P$2+Q10*$Q$2-5*T10+R10*0.25+S10*0.25 -> 81.135 | V10: =ROUNDUP(U10,0) -> 82 | W10: =IFS(V10>=90, "A+", V10>=85, "A", V10>=80, "A-", V10>=77, "B+", V10>=73, "B", V10>=70, "B-", TRUE, "") -> A-
A11: Benjamin GILLARD | B11: e11415026 | C11: BENI | D11: 90 | E11: 84 | F11: 100 | G11: 95 | H11: 88 | I11: 91 | J11: {=_xlfn.XLOOKUP($A11, 'Camping Simulation'!$B:$B, 'Camping Simulation'!$K:$K, "X")} -> 89 | K11: 85 | L11: 88 | M11: 90 | N11: 88 | O11: 95 | P11: 90 | Q11: 88 | U11: =D11*$D$2+E11*$E$2+F11*$F$2+G11*$G$2+H11*$H$2+I11*$I$2+J11*$J$2+K11*$K$2+L11*$L$2+M11*$M$2+N11*$N$2+O11*$O$2+P11*$P$2+Q11*$Q$2-5*T11+R11*0.25+S11*0.25 -> 90.64 | V11: =ROUNDUP(U11,0) -> 91 | W11: =IFS(V11>=90, "A+", V11>=85, "A", V11>=80, "A-", V11>=77, "B+", V11>=73, "B", V11>=70, "B-", TRUE, "") -> A+
A12: Ugo LINDEPERG | B12: e11415027 | C12: BENI | D12: 90 | E12: 84 | F12: 0 | G12: 95 | H12: 90 | I12: 91 | J12: 88 | K12: 85 | L12: 91 | M12: 88 | N12: 89 | O12: 95 | P12: 92 | Q12: 93 | U12: =D12*$D$2+E12*$E$2+F12*$F$2+G12*$G$2+H12*$H$2+I12*$I$2+J12*$J$2+K12*$K$2+L12*$L$2+M12*$M$2+N12*$N$2+O12*$O$2+P12*$P$2+Q12*$Q$2-5*T12+R12*0.25+S12*0.25 -> 80.915 | V12: =ROUNDUP(U12,0) -> 81 | W12: =IFS(V12>=90, "A+", V12>=85, "A", V12>=80, "A-", V12>=77, "B+", V12>=73, "B", V12>=70, "B-", TRUE, "") -> A-
A13: Oriiana Nedzelska | B13: f11415026 | C13: BENI | D13: 90 | E13: 84 | F13: 100 | G13: 95 | H13: 90 | I13: 91 | J13: {=_xlfn.XLOOKUP($A13, 'Camping Simulation'!$B:$B, 'Camping Simulation'!$K:$K, "X")} -> 92 | K13: 85 | L13: 92 | M13: 91 | N13: 93 | O13: 95 | P13: 93 | Q13: 92 | R13: 1 | S13: 1 | U13: =D13*$D$2+E13*$E$2+F13*$F$2+G13*$G$2+H13*$H$2+I13*$I$2+J13*$J$2+K13*$K$2+L13*$L$2+M13*$M$2+N13*$N$2+O13*$O$2+P13*$P$2+Q13*$Q$2-5*T13+R13*0.25+S13*0.25 -> 91.895 | V13: =ROUNDUP(U13,0) -> 92 | W13: =IFS(V13>=90, "A+", V13>=85, "A", V13>=80, "A-", V13>=77, "B+", V13>=73, "B", V13>=70, "B-", TRUE, "") -> A+
A14: Lise ZHENG | B14: f11402009 | C14: Cyber Punk | D14: 83 | E14: 90 | F14: 0 | G14: 92 | H14: 88 | I14: 92 | J14: 90 | K14: 88 | L14: 90 | M14: 89 | N14: 89 | O14: 92 | P14: 90 | Q14: 91 | U14: =D14*$D$2+E14*$E$2+F14*$F$2+G14*$G$2+H14*$H$2+I14*$I$2+J14*$J$2+K14*$K$2+L14*$L$2+M14*$M$2+N14*$N$2+O14*$O$2+P14*$P$2+Q14*$Q$2-5*T14+R14*0.25+S14*0.25 -> 80.545 | V14: =ROUNDUP(U14,0) -> 81 | W14: =IFS(V14>=90, "A+", V14>=85, "A", V14>=80, "A-", V14>=77, "B+", V14>=73, "B", V14>=70, "B-", TRUE, "") -> A-
A15: 柯議翔 | B15: M11407319 | C15: Cyber Punk | D15: 83 | E15: 90 | F15: 100 | G15: 92 | H15: 86 | I15: 92 | J15: {=_xlfn.XLOOKUP($A15, 'Camping Simulation'!$B:$B, 'Camping Simulation'!$K:$K, "X")} -> 90 | K15: 88 | L15: 92 | M15: 94 | N15: 90 | O15: 92 | P15: 93 | Q15: 91 | U15: =D15*$D$2+E15*$E$2+F15*$F$2+G15*$G$2+H15*$H$2+I15*$I$2+J15*$J$2+K15*$K$2+L15*$L$2+M15*$M$2+N15*$N$2+O15*$O$2+P15*$P$2+Q15*$Q$2-5*T15+R15*0.25+S15*0.25 -> 91 | V15: =ROUNDUP(U15,0) -> 91 | W15: =IFS(V15>=90, "A+", V15>=85, "A", V15>=80, "A-", V15>=77, "B+", V15>=73, "B", V15>=70, "B-", TRUE, "") -> A+
A16: 盛爾君 | B16: M11407501 | C16: Cyber Punk | D16: 83 | E16: 90 | F16: 100 | G16: 92 | H16: 87 | I16: 92 | J16: {=_xlfn.XLOOKUP($A16, 'Camping Simulation'!$B:$B, 'Camping Simulation'!$K:$K, "X")} -> 88 | K16: 88 | L16: 90 | M16: 89 | N16: 89 | O16: 92 | P16: 88 | Q16: 89 | U16: =D16*$D$2+E16*$E$2+F16*$F$2+G16*$G$2+H16*$H$2+I16*$I$2+J16*$J$2+K16*$K$2+L16*$L$2+M16*$M$2+N16*$N$2+O16*$O$2+P16*$P$2+Q16*$Q$2-5*T16+R16*0.25+S16*0.25 -> 90.395 | V16: =ROUNDUP(U16,0) -> 91 | W16: =IFS(V16>=90, "A+", V16>=85, "A", V16>=80, "A-", V16>=77, "B+", V16>=73, "B", V16>=70, "B-", TRUE, "") -> A+
A17: 許詠翔 | B17: M11407502 | C17: Cyber Punk | D17: 83 | E17: 90 | F17: 100 | G17: 92 | H17: 90 | I17: 92 | J17: {=_xlfn.XLOOKUP($A17, 'Camping Simulation'!$B:$B, 'Camping Simulation'!$K:$K, "X")} -> 92 | K17: 88 | L17: 94 | M17: 92 | N17: 92 | O17: 92 | P17: 92 | Q17: 92 | U17: =D17*$D$2+E17*$E$2+F17*$F$2+G17*$G$2+H17*$H$2+I17*$I$2+J17*$J$2+K17*$K$2+L17*$L$2+M17*$M$2+N17*$N$2+O17*$O$2+P17*$P$2+Q17*$Q$2-5*T17+R17*0.25+S17*0.25 -> 91.18 | V17: =ROUNDUP(U17,0) -> 92 | W17: =IFS(V17>=90, "A+", V17>=85, "A", V17>=80, "A-", V17>=77, "B+", V17>=73, "B", V17>=70, "B-", TRUE, "") -> A+
A18: 龔效諄 | B18: M11407618 | C18: Cyber Punk | D18: 83 | E18: 90 | F18: 100 | G18: 92 | H18: 88 | I18: 92 | J18: {=_xlfn.XLOOKUP($A18, 'Camping Simulation'!$B:$B, 'Camping Simulation'!$K:$K, "X")} -> 92 | K18: 88 | L18: 91 | M18: 93 | N18: 93 | O18: 92 | P18: 90 | Q18: 89 | R18: 1 | U18: =D18*$D$2+E18*$E$2+F18*$F$2+G18*$G$2+H18*$H$2+I18*$I$2+J18*$J$2+K18*$K$2+L18*$L$2+M18*$M$2+N18*$N$2+O18*$O$2+P18*$P$2+Q18*$Q$2-5*T18+R18*0.25+S18*0.25 -> 91.235 | V18: =ROUNDUP(U18,0) -> 92 | W18: =IFS(V18>=90, "A+", V18>=85, "A", V18>=80, "A-", V18>=77, "B+", V18>=73, "B", V18>=70, "B-", TRUE, "") -> A+
A19: Walfroy, Yves, Francois, SAINT-GUILHEM | B19: e11415031 | C19: Cyber Six | D19: 86 | E19: 90 | F19: 100 | G19: 92 | H19: 87 | I19: 92.5 | J19: 87 | K19: 81 | L19: 90 | M19: 0 | N19: 90 | O19: 92 | P19: 87 | Q19: 86 | U19: =D19*$D$2+E19*$E$2+F19*$F$2+G19*$G$2+H19*$H$2+I19*$I$2+J19*$J$2+K19*$K$2+L19*$L$2+M19*$M$2+N19*$N$2+O19*$O$2+P19*$P$2+Q19*$Q$2-5*T19+R19*0.25+S19*0.25 -> 85.165 | V19: =ROUNDUP(U19,0) -> 86 | W19: =IFS(V19>=90, "A+", V19>=85, "A", V19>=80, "A-", V19>=77, "B+", V19>=73, "B", V19>=70, "B-", TRUE, "") -> A
A20: DENNISON SOEDIBJO | B20: f11415018 | C20: Cyber Six | D20: 86 | E20: 90 | F20: 100 | G20: 92 | H20: 87 | I20: 92.5 | J20: {=_xlfn.XLOOKUP($A20, 'Camping Simulation'!$B:$B, 'Camping Simulation'!$K:$K, "X")} -> 91 | K20: 81 | L20: 90 | M20: 80 | N20: 80 | O20: 92 | P20: 80 | Q20: 80 | U20: =D20*$D$2+E20*$E$2+F20*$F$2+G20*$G$2+H20*$H$2+I20*$I$2+J20*$J$2+K20*$K$2+L20*$L$2+M20*$M$2+N20*$N$2+O20*$O$2+P20*$P$2+Q20*$Q$2-5*T20+R20*0.25+S20*0.25 -> 88.42 | V20: =ROUNDUP(U20,0) -> 89 | W20: =IFS(V20>=90, "A+", V20>=85, "A", V20>=80, "A-", V20>=77, "B+", V20>=73, "B", V20>=70, "B-", TRUE, "") -> A
A21: DIVEN DECHAL JATIPUTRA | B21: f11415019 | C21: Cyber Six | D21: 86 | E21: 90 | F21: 100 | G21: 92 | H21: 89 | I21: 92.5 | J21: {=_xlfn.XLOOKUP($A21, 'Camping Simulation'!$B:$B, 'Camping Simulation'!$K:$K, "X")} -> 89 | K21: 81 | L21: 91 | M21: 93 | N21: 92 | O21: 92 | P21: 80 | Q21: 92 | U21: =D21*$D$2+E21*$E$2+F21*$F$2+G21*$G$2+H21*$H$2+I21*$I$2+J21*$J$2+K21*$K$2+L21*$L$2+M21*$M$2+N21*$N$2+O21*$O$2+P21*$P$2+Q21*$Q$2-5*T21+R21*0.25+S21*0.25 -> 90 | V21: =ROUNDUP(U21,0) -> 90 | W21: =IFS(V21>=90, "A+", V21>=85, "A", V21>=80, "A-", V21>=77, "B+", V21>=73, "B", V21>=70, "B-", TRUE, "") -> A+
A22: JOSHUA PUTRA PRATAMA | B22: f11415027 | C22: Cyber Six | D22: 86 | E22: 90 | F22: 100 | G22: 92 | H22: 92 | I22: 92.5 | J22: {=_xlfn.XLOOKUP($A22, 'Camping Simulation'!$B:$B, 'Camping Simulation'!$K:$K, "X")} -> 92 | K22: 81 | L22: 92 | M22: 92 | N22: 93 | O22: 92 | P22: 93 | Q22: 93 | U22: =D22*$D$2+E22*$E$2+F22*$F$2+G22*$G$2+H22*$H$2+I22*$I$2+J22*$J$2+K22*$K$2+L22*$L$2+M22*$M$2+N22*$N$2+O22*$O$2+P22*$P$2+Q22*$Q$2-5*T22+R22*0.25+S22*0.25 -> 90.49 | V22: =ROUNDUP(U22,0) -> 91 | W22: =IFS(V22>=90, "A+", V22>=85, "A", V22>=80, "A-", V22>=77, "B+", V22>=73, "B", V22>=70, "B-", TRUE, "") -> A+
A23: Rivaldo Yudha Pradana | B23: M11407804 | C23: Cyber Six | D23: 86 | E23: 90 | F23: 100 | G23: 92 | H23: 92 | I23: 92.5 | J23: {=_xlfn.XLOOKUP($A23, 'Camping Simulation'!$B:$B, 'Camping Simulation'!$K:$K, "X")} -> 91 | K23: 81 | L23: 93 | M23: 92 | N23: 93 | O23: 92 | P23: 93 | Q23: 93 | U23: =D23*$D$2+E23*$E$2+F23*$F$2+G23*$G$2+H23*$H$2+I23*$I$2+J23*$J$2+K23*$K$2+L23*$L$2+M23*$M$2+N23*$N$2+O23*$O$2+P23*$P$2+Q23*$Q$2-5*T23+R23*0.25+S23*0.25 -> 90.52 | V23: =ROUNDUP(U23,0) -> 91 | W23: =IFS(V23>=90, "A+", V23>=85, "A", V23>=80, "A-", V23>=77, "B+", V23>=73, "B", V23>=70, "B-", TRUE, "") -> A+
A24: MIKHAEL GERSON SILAEN | B24: m11407809 | C24: Cyber Six | D24: 86 | E24: 90 | F24: 100 | G24: 92 | H24: 91 | I24: 92.5 | J24: {=_xlfn.XLOOKUP($A24, 'Camping Simulation'!$B:$B, 'Camping Simulation'!$K:$K, "X")} -> 92 | K24: 81 | L24: 92 | M24: 91 | N24: 91 | O24: 92 | P24: 93 | Q24: 93 | U24: =D24*$D$2+E24*$E$2+F24*$F$2+G24*$G$2+H24*$H$2+I24*$I$2+J24*$J$2+K24*$K$2+L24*$L$2+M24*$M$2+N24*$N$2+O24*$O$2+P24*$P$2+Q24*$Q$2-5*T24+R24*0.25+S24*0.25 -> 90.33 | V24: =ROUNDUP(U24,0) -> 91 | W24: =IFS(V24>=90, "A+", V24>=85, "A", V24>=80, "A-", V24>=77, "B+", V24>=73, "B", V24>=70, "B-", TRUE, "") -> A+
A25: Peter Jonathan Kuhn | B25: e11415021 | C25: European Avalanche | D25: 90 | E25: 84 | F25: 100 | G25: 92 | H25: 92 | I25: 91 | J25: 88 | K25: 90 | L25: 89 | M25: 0 | N25: 88 | O25: 92 | P25: 91 | Q25: 92 | R25: 1 | U25: =D25*$D$2+E25*$E$2+F25*$F$2+G25*$G$2+H25*$H$2+I25*$I$2+J25*$J$2+K25*$K$2+L25*$L$2+M25*$M$2+N25*$N$2+O25*$O$2+P25*$P$2+Q25*$Q$2-5*T25+R25*0.25+S25*0.25 -> 86.615 | V25: =ROUNDUP(U25,0) -> 87 | W25: =IFS(V25>=90, "A+", V25>=85, "A", V25>=80, "A-", V25>=77, "B+", V25>=73, "B", V25>=70, "B-", TRUE, "") -> A
A26: Ayman Rabih Kallouz | B26: e11415023 | C26: European Avalanche | D26: 90 | E26: 84 | F26: 100 | G26: 92 | H26: 88 | I26: 91 | J26: 0 | K26: 90 | L26: 89 | M26: 88 | N26: 90 | O26: 92 | P26: 92 | Q26: 92 | U26: =D26*$D$2+E26*$E$2+F26*$F$2+G26*$G$2+H26*$H$2+I26*$I$2+J26*$J$2+K26*$K$2+L26*$L$2+M26*$M$2+N26*$N$2+O26*$O$2+P26*$P$2+Q26*$Q$2-5*T26+R26*0.25+S26*0.25 -> 89.09 | V26: =ROUNDUP(U26,0) -> 90 | W26: =IFS(V26>=90, "A+", V26>=85, "A", V26>=80, "A-", V26>=77, "B+", V26>=73, "B", V26>=70, "B-", TRUE, "") -> A+
A27: Andreas Leeb | B27: e11415025 | C27: European Avalanche | D27: 90 | E27: 84 | F27: 100 | G27: 92 | H27: 90 | I27: 91 | J27: {=_xlfn.XLOOKUP($A27, 'Camping Simulation'!$B:$B, 'Camping Simulation'!$K:$K, "X")} -> 87 | K27: 90 | L27: 89 | M27: 87 | N27: 89 | O27: 92 | P27: 90 | Q27: 0 | U27: =D27*$D$2+E27*$E$2+F27*$F$2+G27*$G$2+H27*$H$2+I27*$I$2+J27*$J$2+K27*$K$2+L27*$L$2+M27*$M$2+N27*$N$2+O27*$O$2+P27*$P$2+Q27*$Q$2-5*T27+R27*0.25+S27*0.25 -> 88.4 | V27: =ROUNDUP(U27,0) -> 89 | W27: =IFS(V27>=90, "A+", V27>=85, "A", V27>=80, "A-", V27>=77, "B+", V27>=73, "B", V27>=70, "B-", TRUE, "") -> A
A28: Adam Pach | B28: e11415030 | C28: European Avalanche | D28: 90 | E28: 84 | F28: 100 | G28: 92 | H28: 88 | I28: 91 | J28: {=_xlfn.XLOOKUP($A28, 'Camping Simulation'!$B:$B, 'Camping Simulation'!$K:$K, "X")} -> 89 | K28: 90 | L28: 90 | M28: 88 | N28: 92 | O28: 92 | P28: 88 | Q28: 89 | U28: =D28*$D$2+E28*$E$2+F28*$F$2+G28*$G$2+H28*$H$2+I28*$I$2+J28*$J$2+K28*$K$2+L28*$L$2+M28*$M$2+N28*$N$2+O28*$O$2+P28*$P$2+Q28*$Q$2-5*T28+R28*0.25+S28*0.25 -> 90.845 | V28: =ROUNDUP(U28,0) -> 91 | W28: =IFS(V28>=90, "A+", V28>=85, "A", V28>=80, "A-", V28>=77, "B+", V28>=73, "B", V28>=70, "B-", TRUE, "") -> A+
A29: Bernardo Cavalcante Vieira de Andrade | B29: e11423008 | C29: European Avalanche | D29: 90 | E29: 84 | F29: 100 | G29: 92 | H29: 87 | I29: 91 | J29: 92 | K29: 90 | L29: 0 | M29: 90 | N29: 94 | O29: 92 | P29: 92 | Q29: 0 | U29: =D29*$D$2+E29*$E$2+F29*$F$2+G29*$G$2+H29*$H$2+I29*$I$2+J29*$J$2+K29*$K$2+L29*$L$2+M29*$M$2+N29*$N$2+O29*$O$2+P29*$P$2+Q29*$Q$2-5*T29+R29*0.25+S29*0.25 -> 84.47 | V29: =ROUNDUP(U29,0) -> 85 | W29: =IFS(V29>=90, "A+", V29>=85, "A", V29>=80, "A-", V29>=77, "B+", V29>=73, "B", V29>=70, "B-", TRUE, "") -> A
A30: Lucas Metzger | B30: f11415020 | C30: European Avalanche | D30: 90 | E30: 84 | F30: 100 | G30: 92 | H30: 87 | I30: 91 | J30: {=_xlfn.XLOOKUP($A30, 'Camping Simulation'!$B:$B, 'Camping Simulation'!$K:$K, "X")} -> 87 | K30: 90 | L30: 88 | M30: 88 | N30: 87 | O30: 92 | P30: 90 | Q30: 91 | U30: =D30*$D$2+E30*$E$2+F30*$F$2+G30*$G$2+H30*$H$2+I30*$I$2+J30*$J$2+K30*$K$2+L30*$L$2+M30*$M$2+N30*$N$2+O30*$O$2+P30*$P$2+Q30*$Q$2-5*T30+R30*0.25+S30*0.25 -> 90.545 | V30: =ROUNDUP(U30,0) -> 91 | W30: =IFS(V30>=90, "A+", V30>=85, "A", V30>=80, "A-", V30>=77, "B+", V30>=73, "B", V30>=70, "B-", TRUE, "") -> A+
A31: ITSUKI KURIYAMA | B31: F11415005 | C31: GPT+ | D31: 83 | E31: 88 | F31: 100 | G31: 91 | H31: 0 | I31: 90 | J31: 0 | K31: 78 | L31: 94 | M31: 93 | N31: 92 | O31: 91 | P31: 92 | Q31: 92 | R31: 1 | U31: =D31*$D$2+E31*$E$2+F31*$F$2+G31*$G$2+H31*$H$2+I31*$I$2+J31*$J$2+K31*$K$2+L31*$L$2+M31*$M$2+N31*$N$2+O31*$O$2+P31*$P$2+Q31*$Q$2-5*T31+R31*0.25+S31*0.25 -> 86.64 | V31: =ROUNDUP(U31,0) -> 87 | W31: =IFS(V31>=90, "A+", V31>=85, "A", V31>=80, "A-", V31>=77, "B+", V31>=73, "B", V31>=70, "B-", TRUE, "") -> A
A32: 祖祥恩 | B32: M11307310 | C32: GPT+ | D32: 83 | E32: 88 | F32: 100 | G32: 91 | H32: 85 | I32: 90 | J32: {=_xlfn.XLOOKUP($A32, 'Camping Simulation'!$B:$B, 'Camping Simulation'!$K:$K, "X")} -> 87 | K32: 78 | L32: 90 | M32: 90 | N32: 92 | O32: 91 | P32: 91 | Q32: 90 | U32: =D32*$D$2+E32*$E$2+F32*$F$2+G32*$G$2+H32*$H$2+I32*$I$2+J32*$J$2+K32*$K$2+L32*$L$2+M32*$M$2+N32*$N$2+O32*$O$2+P32*$P$2+Q32*$Q$2-5*T32+R32*0.25+S32*0.25 -> 88.555 | V32: =ROUNDUP(U32,0) -> 89 | W32: =IFS(V32>=90, "A+", V32>=85, "A", V32>=80, "A-", V32>=77, "B+", V32>=73, "B", V32>=70, "B-", TRUE, "") -> A
A33: 葉人瑋 | B33: m11407437 | C33: GPT+ | D33: 83 | E33: 88 | F33: 100 | G33: 91 | H33: 85 | I33: 90 | J33: {=_xlfn.XLOOKUP($A33, 'Camping Simulation'!$B:$B, 'Camping Simulation'!$K:$K, "X")} -> 89 | K33: 78 | L33: 90 | M33: 89 | N33: 90 | O33: 91 | P33: 85 | Q33: 0 | U33: =D33*$D$2+E33*$E$2+F33*$F$2+G33*$G$2+H33*$H$2+I33*$I$2+J33*$J$2+K33*$K$2+L33*$L$2+M33*$M$2+N33*$N$2+O33*$O$2+P33*$P$2+Q33*$Q$2-5*T33+R33*0.25+S33*0.25 -> 86.045 | V33: =ROUNDUP(U33,0) -> 87 | W33: =IFS(V33>=90, "A+", V33>=85, "A", V33>=80, "A-", V33>=77, "B+", V33>=73, "B", V33>=70, "B-", TRUE, "") -> A
A34: 蔡哲維 | B34: m11407524 | C34: GPT+ | D34: 83 | E34: 88 | F34: 100 | G34: 91 | H34: 0 | I34: 90 | J34: 0 | K34: 78 | L34: 90 | M34: 89 | N34: 90 | O34: 91 | P34: 0 | Q34: 87 | U34: =D34*$D$2+E34*$E$2+F34*$F$2+G34*$G$2+H34*$H$2+I34*$I$2+J34*$J$2+K34*$K$2+L34*$L$2+M34*$M$2+N34*$N$2+O34*$O$2+P34*$P$2+Q34*$Q$2-5*T34+R34*0.25+S34*0.25 -> 83.465 | V34: =ROUNDUP(U34,0) -> 84 | W34: =IFS(V34>=90, "A+", V34>=85, "A", V34>=80, "A-", V34>=77, "B+", V34>=73, "B", V34>=70, "B-", TRUE, "") -> A-
A35: 陳增勇 | B35: B11007106 | C35: Insect | D35: 92 | E35: 94 | F35: 100 | G35: 95 | H35: 88 | I35: 83 | J35: {=_xlfn.XLOOKUP($A35, 'Camping Simulation'!$B:$B, 'Camping Simulation'!$K:$K, "X")} -> 92 | K35: 82 | L35: 0 | M35: 91 | N35: 90 | O35: 95 | P35: 93 | Q35: 93 | U35: =D35*$D$2+E35*$E$2+F35*$F$2+G35*$G$2+H35*$H$2+I35*$I$2+J35*$J$2+K35*$K$2+L35*$L$2+M35*$M$2+N35*$N$2+O35*$O$2+P35*$P$2+Q35*$Q$2-5*T35+R35*0.25+S35*0.25 -> 86.76 | V35: =ROUNDUP(U35,0) -> 87 | W35: =IFS(V35>=90, "A+", V35>=85, "A", V35>=80, "A-", V35>=77, "B+", V35>=73, "B", V35>=70, "B-", TRUE, "") -> A
A36: Laina Farsiah | B36: D11415802 | C36: Insect | D36: 92 | E36: 94 | F36: 100 | G36: 95 | H36: 95 | I36: 83 | J36: {=_xlfn.XLOOKUP($A36, 'Camping Simulation'!$B:$B, 'Camping Simulation'!$K:$K, "X")} -> 94 | K36: 82 | L36: 92 | M36: 92 | N36: 95 | O36: 95 | P36: 94 | Q36: 94 | R36: 1 | U36: =D36*$D$2+E36*$E$2+F36*$F$2+G36*$G$2+H36*$H$2+I36*$I$2+J36*$J$2+K36*$K$2+L36*$L$2+M36*$M$2+N36*$N$2+O36*$O$2+P36*$P$2+Q36*$Q$2-5*T36+R36*0.25+S36*0.25 -> 92.07 | V36: =ROUNDUP(U36,0) -> 93 | W36: =IFS(V36>=90, "A+", V36>=85, "A", V36>=80, "A-", V36>=77, "B+", V36>=73, "B", V36>=70, "B-", TRUE, "") -> A+
A37: Alim Misbullah | B37: D11415803 | C37: Insect | D37: 92 | E37: 94 | F37: 100 | G37: 95 | H37: 90 | I37: 83 | J37: {=_xlfn.XLOOKUP($A37, 'Camping Simulation'!$B:$B, 'Camping Simulation'!$K:$K, "X")} -> 93 | K37: 82 | L37: 92 | M37: 90 | N37: 91 | O37: 95 | P37: 91 | Q37: 93 | R37: 1 | U37: =D37*$D$2+E37*$E$2+F37*$F$2+G37*$G$2+H37*$H$2+I37*$I$2+J37*$J$2+K37*$K$2+L37*$L$2+M37*$M$2+N37*$N$2+O37*$O$2+P37*$P$2+Q37*$Q$2-5*T37+R37*0.25+S37*0.25 -> 91.6 | V37: =ROUNDUP(U37,0) -> 92 | W37: =IFS(V37>=90, "A+", V37>=85, "A", V37>=80, "A-", V37>=77, "B+", V37>=73, "B", V37>=70, "B-", TRUE, "") -> A+
A38: Danis Putra Perdana | B38: D11415806 | C38: Insect | D38: 92 | E38: 94 | F38: 100 | G38: 95 | H38: 90 | I38: 83 | J38: {=_xlfn.XLOOKUP($A38, 'Camping Simulation'!$B:$B, 'Camping Simulation'!$K:$K, "X")} -> 89 | K38: 82 | L38: 90 | M38: 91 | N38: 90 | O38: 95 | P38: 88 | Q38: 89 | R38: 1 | U38: =D38*$D$2+E38*$E$2+F38*$F$2+G38*$G$2+H38*$H$2+I38*$I$2+J38*$J$2+K38*$K$2+L38*$L$2+M38*$M$2+N38*$N$2+O38*$O$2+P38*$P$2+Q38*$Q$2-5*T38+R38*0.25+S38*0.25 -> 91.245 | V38: =ROUNDUP(U38,0) -> 92 | W38: =IFS(V38>=90, "A+", V38>=85, "A", V38>=80, "A-", V38>=77, "B+", V38>=73, "B", V38>=70, "B-", TRUE, "") -> A+
A39: Puspa Ira Dewi Candra Wulan | B39: D11415807 | C39: Insect | D39: 92 | E39: 94 | F39: 100 | G39: 95 | H39: 88 | I39: 83 | J39: {=_xlfn.XLOOKUP($A39, 'Camping Simulation'!$B:$B, 'Camping Simulation'!$K:$K, "X")} -> 90 | K39: 82 | L39: 93 | M39: 91 | N39: 89 | O39: 95 | P39: 93 | Q39: 91 | R39: 1 | S39: 1 | U39: =D39*$D$2+E39*$E$2+F39*$F$2+G39*$G$2+H39*$H$2+I39*$I$2+J39*$J$2+K39*$K$2+L39*$L$2+M39*$M$2+N39*$N$2+O39*$O$2+P39*$P$2+Q39*$Q$2-5*T39+R39*0.25+S39*0.25 -> 91.77 | V39: =ROUNDUP(U39,0) -> 92 | W39: =IFS(V39>=90, "A+", V39>=85, "A", V39>=80, "A-", V39>=77, "B+", V39>=73, "B", V39>=70, "B-", TRUE, "") -> A+
A40: Aurelio Naufal Effendy | B40: M11415802 | C40: Insect | D40: 92 | E40: 94 | F40: 100 | G40: 95 | H40: 90 | I40: 83 | J40: {=_xlfn.XLOOKUP($A40, 'Camping Simulation'!$B:$B, 'Camping Simulation'!$K:$K, "X")} -> 95 | K40: 82 | L40: 92 | M40: 92 | N40: 92 | O40: 95 | P40: 90 | Q40: 92 | U40: =D40*$D$2+E40*$E$2+F40*$F$2+G40*$G$2+H40*$H$2+I40*$I$2+J40*$J$2+K40*$K$2+L40*$L$2+M40*$M$2+N40*$N$2+O40*$O$2+P40*$P$2+Q40*$Q$2-5*T40+R40*0.25+S40*0.25 -> 91.49 | V40: =ROUNDUP(U40,0) -> 92 | W40: =IFS(V40>=90, "A+", V40>=85, "A", V40>=80, "A-", V40>=77, "B+", V40>=73, "B", V40>=70, "B-", TRUE, "") -> A+
...

Sheet Grade
A1: 名字 | B1: 學號 | C1: 分組 | D1: Cybersecurity news presentation | E1: CTI report slide | F1: Malware analysis | G1: Cuckoo slide/json | H1: Machine learning in malware analysis | I1: Project Proposal | J1: Project Proposal Form | K1: Project Proposal Slide | L1: Red team practice | M1: Caldera Form | N1: Caldera Slide+md+json+proco | O1: Paper presentation | P1: Week 12 - Paper Form | Q1: Week 13 - Paper Form | R1: Week 14 - Paper Form | S1: Paper slide | T1: Final Project 老師 | U1: Final Project Form 1 | V1: Final Project Form 2 | W1: Final Project md+code/log+slide | X1: Cybersec 2026 心得 | Y1: LLM 回答 | Z1: 缺席 | AA1: 總分 | AD1: Name | AF1: Name
D2: 0.1 | E2: // | F2: 0.1 | G2: // | H2: 0.1 | I2: 0.04 | J2: 0.01 | K2: // | L2: 0.08 | M2: 0.02 | N2: // | O2: 0.15 | P2: 0.05 | Q2: 0.05 | R2: 0.05 | S2: // | T2: 0.2 | U2: 0.025 | V2: 0.025 | W2: // | X2: bonus | Y2: bonus | AD2: W12
A3: 黃文良 | B3: B11107152 | C3: ANTSLAB | D3: 86 | E3: 1 | F3: 94 | G3: 1 | H3: 100 | I3: 95 | J3: 86 | K3: 1 | L3: 93 | M3: {=_xlfn.XLOOKUP($A3, 'Camping Simulation'!$B:$B, 'Camping Simulation'!$K:$K, "X")} -> 87 | N3: 0 | O3: 94 | P3: {=_xlfn.XLOOKUP($B3, 'W12 paper end'!$C:$C, 'W12 paper end'!$L:$L, "0")} -> 89 | Q3: {=_xlfn.XLOOKUP($B3, 'W13 paper end'!$C:$C, 'W13 paper end'!$L:$L, "0")} -> 89 | R3: {=_xlfn.XLOOKUP($B3, 'W14 paper end'!$C:$C, 'W14 paper end'!$K:$K, "0")} -> 89 | S3: 1 | T3: 95 | U3: 86 | V3: 0 | W3: 1 | X3: {=IF(ISNA(_xlfn.XLOOKUP(U3, AB:AB, AB:AB)), "", "✔")} | Z3: 1 | AA3: =D3*$D$2+F3*$F$2+H3*$H$2+I3*$I$2+J3*$J$2+L3*$L$2+M3*$M$2+O3*$O$2+P3*$P$2+Q3*$Q$2+R3*$R$2+T3*$T$2+U3*$U$2+V3*$V$2-5*Z3 -> 85.44 | AD3: Su Yadana Win | AE3: =IF(COUNTIF($A:$A, AD3)>0, "✓", "") -> ✓ | AF3: Su Yadana Win | AG3: =IF(COUNTIF($A:$A, AF3)>0, "✓", "") -> ✓
A4: 胡承學 | B4: B11107153 | C4: ANTSLAB | D4: 86 | E4: 1 | F4: 94 | G4: 1 | H4: 0 | I4: 95 | J4: 0 | K4: 1 | L4: 93 | M4: {=_xlfn.XLOOKUP($A4, 'Camping Simulation'!$B:$B, 'Camping Simulation'!$K:$K, "X")} -> 90 | N4: 0 | O4: 94 | P4: {=_xlfn.XLOOKUP($B4, 'W12 paper end'!$C:$C, 'W12 paper end'!$L:$L, "X")} -> 90 | Q4: {=_xlfn.XLOOKUP($B4, 'W13 paper end'!$C:$C, 'W13 paper end'!$L:$L, "0")} -> 90 | R4: {=_xlfn.XLOOKUP($B4, 'W14 paper end'!$C:$C, 'W14 paper end'!$K:$K, "0")} -> 90 | S4: 1 | T4: 95 | U4: 88 | V4: 89 | W4: 1 | AA4: =D4*$D$2+F4*$F$2+H4*$H$2+I4*$I$2+J4*$J$2+L4*$L$2+M4*$M$2+O4*$O$2+P4*$P$2+Q4*$Q$2+R4*$R$2+T4*$T$2+U4*$U$2+V4*$V$2-5*Z4 -> 82.065 | AD4: Peter Jonathan Kuhn | AE4: =IF(COUNTIF(A:A, AD4)>0, "✓", "") -> ✓ | AF4: 葉人瑋 | AG4: =IF(COUNTIF($A:$A, AF4)>0, "✓", "") -> ✓
A5: 吳永保 | B5: M11407005 | C5: ANTSLAB | D5: 86 | E5: 1 | F5: 94 | G5: 1 | H5: 100 | I5: 95 | J5: 88 | K5: 1 | L5: 93 | M5: {=_xlfn.XLOOKUP($A5, 'Camping Simulation'!$B:$B, 'Camping Simulation'!$K:$K, "X")} -> 89 | N5: 0 | O5: 94 | P5: {=_xlfn.XLOOKUP($B5, 'W12 paper end'!$C:$C, 'W12 paper end'!$L:$L, "X")} -> 92 | Q5: {=_xlfn.XLOOKUP($B5, 'W13 paper end'!$C:$C, 'W13 paper end'!$L:$L, "0")} -> 90 | R5: {=_xlfn.XLOOKUP($B5, 'W14 paper end'!$B:$B, 'W14 paper end'!$K:$K, "0")} -> 92 | S5: 1 | T5: 95 | U5: 89 | V5: 92 | W5: 1 | AA5: =D5*$D$2+F5*$F$2+H5*$H$2+I5*$I$2+J5*$J$2+L5*$L$2+M5*$M$2+O5*$O$2+P5*$P$2+Q5*$Q$2+R5*$R$2+T5*$T$2+U5*$U$2+V5*$V$2-5*Z5 -> 93.225 | AD5: 蔡哲維 | AE5: =IF(COUNTIF(A:A, AD5)>0, "✓", "") -> ✓ | AF5: 祖祥恩 | AG5: =IF(COUNTIF($A:$A, AF5)>0, "✓", "") -> ✓
A6: 楊晴安 | B6: M11407507 | C6: ANTSLAB | D6: 86 | E6: 1 | F6: 94 | G6: 1 | H6: 100 | I6: 95 | J6: 89 | K6: 1 | L6: 93 | M6: {=_xlfn.XLOOKUP($A6, 'Camping Simulation'!$B:$B, 'Camping Simulation'!$K:$K, "X")} -> 92 | N6: 0 | O6: 94 | P6: {=_xlfn.XLOOKUP($B6, 'W12 paper end'!$C:$C, 'W12 paper end'!$L:$L, "X")} -> 93 | Q6: {=_xlfn.XLOOKUP($B6, 'W13 paper end'!$C:$C, 'W13 paper end'!$L:$L, "0")} -> 91 | R6: {=_xlfn.XLOOKUP($B6, 'W14 paper end'!$C:$C, 'W14 paper end'!$K:$K, "0")} -> 92 | S6: 1 | T6: 95 | U6: 90 | V6: 93 | W6: 1 | X6: V | AA6: =D6*$D$2+F6*$F$2+H6*$H$2+I6*$I$2+J6*$J$2+L6*$L$2+M6*$M$2+O6*$O$2+P6*$P$2+Q6*$Q$2+R6*$R$2+T6*$T$2+U6*$U$2+V6*$V$2-5*Z6 -> 93.445 | AD6: Lucas Metzger | AE6: =IF(COUNTIF(A:A, AD6)>0, "✓", "") -> ✓ | AF6: Laina Farsiah | AG6: =IF(COUNTIF($A:$A, AF6)>0, "✓", "") -> ✓
A7: 洪粲鈞 | B7: M11407519 | C7: ANTSLAB | D7: 86 | E7: 1 | F7: 94 | G7: 1 | H7: 100 | I7: 95 | J7: 93 | K7: 1 | L7: 93 | M7: {=_xlfn.XLOOKUP($A7, 'Camping Simulation'!$B:$B, 'Camping Simulation'!$K:$K, "X")} -> 89 | N7: 0 | O7: 94 | P7: {=_xlfn.XLOOKUP($B7, 'W12 paper end'!$C:$C, 'W12 paper end'!$L:$L, "0")} -> 90 | Q7: {=_xlfn.XLOOKUP($B7, 'W13 paper end'!$C:$C, 'W13 paper end'!$L:$L, "0")} -> 92 | R7: {=_xlfn.XLOOKUP($B7, 'W14 paper end'!$C:$C, 'W14 paper end'!$K:$K, "0")} -> 91 | S7: 1 | T7: 95 | U7: 90 | V7: 90 | W7: 1 | X7: V | AA7: =D7*$D$2+F7*$F$2+H7*$H$2+I7*$I$2+J7*$J$2+L7*$L$2+M7*$M$2+O7*$O$2+P7*$P$2+Q7*$Q$2+R7*$R$2+T7*$T$2+U7*$U$2+V7*$V$2-5*Z7 -> 93.2 | AD7: Ayman Kallouz | AE7: =IF(COUNTIF(A:A, AD7)>0, "✓", "") | AF7: 龔效諄 | AG7: =IF(COUNTIF($A:$A, AF7)>0, "✓", "") -> ✓
A8: 張惟凱 | B8: M11407522 | C8: ANTSLAB | D8: 86 | E8: 1 | F8: 94 | G8: 1 | H8: 100 | I8: 95 | J8: 92 | K8: 1 | L8: 93 | M8: {=_xlfn.XLOOKUP($A8, 'Camping Simulation'!$B:$B, 'Camping Simulation'!$K:$K, "X")} -> 92 | N8: 0 | O8: 94 | P8: {=_xlfn.XLOOKUP($B8, 'W12 paper end'!$C:$C, 'W12 paper end'!$L:$L, "X")} -> 92 | Q8: {=_xlfn.XLOOKUP($B8, 'W13 paper end'!$C:$C, 'W13 paper end'!$L:$L, "0")} -> 91 | R8: {=_xlfn.XLOOKUP($B8, 'W14 paper end'!$C:$C, 'W14 paper end'!$K:$K, "0")} -> 93 | S8: 1 | T8: 95 | U8: 94 | V8: 93 | W8: 1 | X8: V | AA8: =D8*$D$2+F8*$F$2+H8*$H$2+I8*$I$2+J8*$J$2+L8*$L$2+M8*$M$2+O8*$O$2+P8*$P$2+Q8*$Q$2+R8*$R$2+T8*$T$2+U8*$U$2+V8*$V$2-5*Z8 -> 93.575 | AD8: 祖祥恩 | AE8: =IF(COUNTIF(A:A, AD8)>0, "✓", "") -> ✓ | AF8: Puspa Ira Dewi Candra Wulan | AG8: =IF(COUNTIF($A:$A, AF8)>0, "✓", "") -> ✓
A9: SU YADANA WIN | B9: d11415809 | C9: BENI | D9: 90 | E9: 1 | F9: 84 | G9: 1 | H9: 100 | I9: 95 | J9: 88 | K9: 1 | L9: 91 | M9: 0 | N9: 1 | O9: 85 | P9: {=_xlfn.XLOOKUP($B9, 'W12 paper end'!$C:$C, 'W12 paper end'!$L:$L, "X")} -> 94 | Q9: {=_xlfn.XLOOKUP($B9, 'W13 paper end'!$C:$C, 'W13 paper end'!$L:$L, "0")} -> 91 | R9: {=_xlfn.XLOOKUP($B9, 'W14 paper end'!$C:$C, 'W14 paper end'!$K:$K, "0")} -> 90 | S9: 1 | T9: 95 | U9: 95 | V9: 95 | W9: 1 | X9: V | AA9: =D9*$D$2+F9*$F$2+H9*$H$2+I9*$I$2+J9*$J$2+L9*$L$2+M9*$M$2+O9*$O$2+P9*$P$2+Q9*$Q$2+R9*$R$2+T9*$T$2+U9*$U$2+V9*$V$2-5*Z9 -> 89.61 | AD9: Benjamin Gillard | AE9: =IF(COUNTIF(A:A, AD9)>0, "✓", "") -> ✓ | AF9: ZHENG Lise | AG9: =IF(COUNTIF($A:$A, AF9)>0, "✓", "")
A10: Jules GIRARD | B10: e11415022 | C10: BENI | D10: 90 | E10: 1 | F10: 84 | G10: 1 | H10: 0 | I10: 95 | J10: 90 | K10: 1 | L10: 91 | M10: {=_xlfn.XLOOKUP($A10, 'Camping Simulation'!$B:$B, 'Camping Simulation'!$K:$K, "X")} -> 89 | N10: 1 | O10: 85 | P10: {=_xlfn.XLOOKUP($B10, 'W12 paper end'!$C:$C, 'W12 paper end'!$L:$L, "0")} -> 91 | Q10: {=_xlfn.XLOOKUP($B10, 'W13 paper end'!$C:$C, 'W13 paper end'!$L:$L, "0")} -> 90 | R10: {=_xlfn.XLOOKUP($B10, 'W14 paper end'!$C:$C, 'W14 paper end'!$K:$K, "0")} -> 91 | S10: 1 | T10: 95 | U10: 92 | V10: 93 | W10: 1 | AA10: =D10*$D$2+F10*$F$2+H10*$H$2+I10*$I$2+J10*$J$2+L10*$L$2+M10*$M$2+O10*$O$2+P10*$P$2+Q10*$Q$2+R10*$R$2+T10*$T$2+U10*$U$2+V10*$V$2-5*Z10 -> 81.135 | AD10: 柯議翔 | AE10: =IF(COUNTIF(A:A, AD10)>0, "✓", "") -> ✓ | AF10: danis putra perdana | AG10: =IF(COUNTIF($A:$A, AF10)>0, "✓", "") -> ✓
A11: Benjamin GILLARD | B11: e11415026 | C11: BENI | D11: 90 | E11: 1 | F11: 84 | G11: 1 | H11: 100 | I11: 95 | J11: 88 | K11: 1 | L11: 91 | M11: {=_xlfn.XLOOKUP($A11, 'Camping Simulation'!$B:$B, 'Camping Simulation'!$K:$K, "X")} -> 89 | N11: 1 | O11: 85 | P11: {=_xlfn.XLOOKUP($B11, 'W12 paper end'!$C:$C, 'W12 paper end'!$L:$L, "0")} -> 88 | Q11: {=_xlfn.XLOOKUP($B11, 'W13 paper end'!$C:$C, 'W13 paper end'!$L:$L, "0")} -> 90 | R11: {=_xlfn.XLOOKUP($B11, 'W14 paper end'!$C:$C, 'W14 paper end'!$K:$K, "0")} -> 88 | S11: 1 | T11: 95 | U11: 90 | V11: 88 | W11: 1 | AA11: =D11*$D$2+F11*$F$2+H11*$H$2+I11*$I$2+J11*$J$2+L11*$L$2+M11*$M$2+O11*$O$2+P11*$P$2+Q11*$Q$2+R11*$R$2+T11*$T$2+U11*$U$2+V11*$V$2-5*Z11 -> 90.64 | AD11: 龔效諄 | AE11: =IF(COUNTIF(A:A, AD11)>0, "✓", "") -> ✓ | AF11: Alim Misbullah | AG11: =IF(COUNTIF($A:$A, AF11)>0, "✓", "") -> ✓
A12: Ugo LINDEPERG | B12: e11415027 | C12: BENI | D12: 90 | E12: 1 | F12: 84 | G12: 1 | H12: 0 | I12: 95 | J12: 90 | K12: 1 | L12: 91 | M12: 0 | N12: 1 | O12: 85 | P12: {=_xlfn.XLOOKUP($B12, 'W12 paper end'!$C:$C, 'W12 paper end'!$L:$L, "0")} -> 91 | Q12: {=_xlfn.XLOOKUP($B12, 'W13 paper end'!$C:$C, 'W13 paper end'!$L:$L, "0")} -> 88 | R12: {=_xlfn.XLOOKUP($B12, 'W14 paper end'!$C:$C, 'W14 paper end'!$K:$K, "0")} -> 89 | S12: 1 | T12: 95 | U12: 92 | V12: 93 | W12: 1 | AA12: =D12*$D$2+F12*$F$2+H12*$H$2+I12*$I$2+J12*$J$2+L12*$L$2+M12*$M$2+O12*$O$2+P12*$P$2+Q12*$Q$2+R12*$R$2+T12*$T$2+U12*$U$2+V12*$V$2-5*Z12 -> 79.155 | AD12: Mikhael Gerson Silaen | AE12: =IF(COUNTIF(A:A, AD12)>0, "✓", "") -> ✓ | AF12: Oriiana Nedzelska | AG12: =IF(COUNTIF($A:$A, AF12)>0, "✓", "") -> ✓
A13: Oriiana Nedzelska | B13: f11415026 | C13: BENI | D13: 90 | E13: 1 | F13: 84 | G13: 1 | H13: 100 | I13: 95 | J13: 90 | K13: 1 | L13: 91 | M13: {=_xlfn.XLOOKUP($A13, 'Camping Simulation'!$B:$B, 'Camping Simulation'!$K:$K, "X")} -> 92 | N13: 1 | O13: 85 | P13: {=_xlfn.XLOOKUP($B13, 'W12 paper end'!$C:$C, 'W12 paper end'!$L:$L, "0")} -> 92 | Q13: {=_xlfn.XLOOKUP($B13, 'W13 paper end'!$C:$C, 'W13 paper end'!$L:$L, "0")} -> 91 | R13: {=_xlfn.XLOOKUP($B13, 'W14 paper end'!$C:$C, 'W14 paper end'!$K:$K, "0")} -> 93 | S13: 1 | T13: 95 | U13: 93 | V13: 92 | W13: 1 | X13: V | Y13: V | AA13: =D13*$D$2+F13*$F$2+H13*$H$2+I13*$I$2+J13*$J$2+L13*$L$2+M13*$M$2+O13*$O$2+P13*$P$2+Q13*$Q$2+R13*$R$2+T13*$T$2+U13*$U$2+V13*$V$2-5*Z13 -> 91.395 | AD13: Diven Dechal Jatiputra | AE13: =IF(COUNTIF(A:A, AD13)>0, "✓", "") -> ✓ | AF13: Andreas Leeb | AG13: =IF(COUNTIF($A:$A, AF13)>0, "✓", "") -> ✓
A14: Lise ZHENG | B14: f11402009 | C14: Cyber Punk | D14: 83 | E14: 1 | F14: 90 | G14: 1 | H14: 0 | I14: 92 | J14: 88 | K14: 1 | L14: 92 | M14: 0 | N14: 1 | O14: 88 | P14: {=_xlfn.XLOOKUP($B14, 'W12 paper end'!$C:$C, 'W12 paper end'!$L:$L, "0")} -> 90 | Q14: {=_xlfn.XLOOKUP($B14, 'W13 paper end'!$C:$C, 'W13 paper end'!$L:$L, "0")} -> 89 | R14: {=_xlfn.XLOOKUP($B14, 'W14 paper end'!$C:$C, 'W14 paper end'!$K:$K, "0")} -> 89 | S14: 1 | T14: 92 | U14: 90 | V14: 91 | W14: 1 | AA14: =D14*$D$2+F14*$F$2+H14*$H$2+I14*$I$2+J14*$J$2+L14*$L$2+M14*$M$2+O14*$O$2+P14*$P$2+Q14*$Q$2+R14*$R$2+T14*$T$2+U14*$U$2+V14*$V$2-5*Z14 -> 78.745 | AD14: Adam Pach | AE14: =IF(COUNTIF(A:A, AD14)>0, "✓", "") -> ✓ | AF14: 柯議翔 | AG14: =IF(COUNTIF($A:$A, AF14)>0, "✓", "") -> ✓
A15: 柯議翔 | B15: M11407319 | C15: Cyber Punk | D15: 83 | E15: 1 | F15: 90 | G15: 1 | H15: 100 | I15: 92 | J15: 86 | K15: 1 | L15: 92 | M15: {=_xlfn.XLOOKUP($A15, 'Camping Simulation'!$B:$B, 'Camping Simulation'!$K:$K, "X")} -> 90 | N15: 1 | O15: 88 | P15: {=_xlfn.XLOOKUP($B15, 'W12 paper end'!$C:$C, 'W12 paper end'!$L:$L, "0")} -> 92 | Q15: {=_xlfn.XLOOKUP($B15, 'W13 paper end'!$C:$C, 'W13 paper end'!$L:$L, "0")} -> 94 | R15: {=_xlfn.XLOOKUP($B15, 'W14 paper end'!$C:$C, 'W14 paper end'!$K:$K, "0")} -> 90 | S15: 1 | T15: 92 | U15: 93 | V15: 91 | W15: 1 | AA15: =D15*$D$2+F15*$F$2+H15*$H$2+I15*$I$2+J15*$J$2+L15*$L$2+M15*$M$2+O15*$O$2+P15*$P$2+Q15*$Q$2+R15*$R$2+T15*$T$2+U15*$U$2+V15*$V$2-5*Z15 -> 91 | AD15: 許詠翔 | AE15: =IF(COUNTIF(A:A, AD15)>0, "✓", "") -> ✓ | AF15: Mikhael | AG15: =IF(COUNTIF($A:$A, AF15)>0, "✓", "")
A16: 盛爾君 | B16: M11407501 | C16: Cyber Punk | D16: 83 | E16: 1 | F16: 90 | G16: 1 | H16: 100 | I16: 92 | J16: 87 | K16: 1 | L16: 92 | M16: {=_xlfn.XLOOKUP($A16, 'Camping Simulation'!$B:$B, 'Camping Simulation'!$K:$K, "X")} -> 88 | N16: 1 | O16: 88 | P16: {=_xlfn.XLOOKUP($B16, 'W12 paper end'!$C:$C, 'W12 paper end'!$L:$L, "0")} -> 90 | Q16: {=_xlfn.XLOOKUP($B16, 'W13 paper end'!$C:$C, 'W13 paper end'!$L:$L, "0")} -> 89 | R16: {=_xlfn.XLOOKUP($B16, 'W14 paper end'!$C:$C, 'W14 paper end'!$K:$K, "0")} -> 89 | S16: 1 | T16: 92 | U16: 88 | V16: 89 | W16: 1 | AA16: =D16*$D$2+F16*$F$2+H16*$H$2+I16*$I$2+J16*$J$2+L16*$L$2+M16*$M$2+O16*$O$2+P16*$P$2+Q16*$Q$2+R16*$R$2+T16*$T$2+U16*$U$2+V16*$V$2-5*Z16 -> 90.395 | AD16: GIRARD Jules | AE16: =IF(COUNTIF(A:A, AD16)>0, "✓", "") | AF16: Lucas Metzger | AG16: =IF(COUNTIF($A:$A, AF16)>0, "✓", "") -> ✓
A17: 許詠翔 | B17: M11407502 | C17: Cyber Punk | D17: 83 | E17: 1 | F17: 90 | G17: 1 | H17: 100 | I17: 92 | J17: 90 | K17: 1 | L17: 92 | M17: {=_xlfn.XLOOKUP($A17, 'Camping Simulation'!$B:$B, 'Camping Simulation'!$K:$K, "X")} -> 92 | N17: 1 | O17: 88 | P17: {=_xlfn.XLOOKUP($B17, 'W12 paper end'!$C:$C, 'W12 paper end'!$L:$L, "0")} -> 94 | Q17: {=_xlfn.XLOOKUP($B17, 'W13 paper end'!$C:$C, 'W13 paper end'!$L:$L, "0")} -> 92 | R17: {=_xlfn.XLOOKUP($B17, 'W14 paper end'!$C:$C, 'W14 paper end'!$K:$K, "0")} -> 92 | S17: 1 | T17: 92 | U17: 92 | V17: 92 | W17: 1 | AA17: =D17*$D$2+F17*$F$2+H17*$H$2+I17*$I$2+J17*$J$2+L17*$L$2+M17*$M$2+O17*$O$2+P17*$P$2+Q17*$Q$2+R17*$R$2+T17*$T$2+U17*$U$2+V17*$V$2-5*Z17 -> 91.18 | AD17: Saint Guilhem Walfroy | AE17: =IF(COUNTIF(A:A, AD17)>0, "✓", "") | AF17: 陳增勇 | AG17: =IF(COUNTIF($A:$A, AF17)>0, "✓", "")
A18: 龔效諄 | B18: M11407618 | C18: Cyber Punk | D18: 83 | E18: 1 | F18: 90 | G18: 1 | H18: 100 | I18: 92 | J18: 88 | K18: 1 | L18: 92 | M18: {=_xlfn.XLOOKUP($A18, 'Camping Simulation'!$B:$B, 'Camping Simulation'!$K:$K, "X")} -> 92 | N18: 1 | O18: 88 | P18: {=_xlfn.XLOOKUP($B18, 'W12 paper end'!$C:$C, 'W12 paper end'!$L:$L, "0")} -> 91 | Q18: {=_xlfn.XLOOKUP($B18, 'W13 paper end'!$C:$C, 'W13 paper end'!$L:$L, "0")} -> 93 | R18: {=_xlfn.XLOOKUP($B18, 'W14 paper end'!$C:$C, 'W14 paper end'!$K:$K, "0")} -> 93 | S18: 1 | T18: 92 | U18: 90 | V18: 89 | W18: 1 | X18: V | AA18: =D18*$D$2+F18*$F$2+H18*$H$2+I18*$I$2+J18*$J$2+L18*$L$2+M18*$M$2+O18*$O$2+P18*$P$2+Q18*$Q$2+R18*$R$2+T18*$T$2+U18*$U$2+V18*$V$2-5*Z18 -> 90.985 | AD18: Puspa Ira Dewi Candra Wulan | AE18: =IF(COUNTIF(A:A, AD18)>0, "✓", "") | AF18: Rivaldo Yudha Pradana | AG18: =IF(COUNTIF($A:$A, AF18)>0, "✓", "") -> ✓
A19: Walfroy, Yves, Francois, SAINT-GUILHEM | B19: e11415031 | C19: Cyber Si0 | D19: 86 | E19: 1 | F19: 90 | G19: 1 | H19: 100 | I19: 92 | J19: 87 | K19: 1 | L19: 92.5 | M19: 0 | N19: 1 | O19: 81 | P19: {=_xlfn.XLOOKUP($B19, 'W12 paper end'!$C:$C, 'W12 paper end'!$L:$L, "0")} -> 90 | Q19: {=_xlfn.XLOOKUP($B19, 'W13 paper end'!$C:$C, 'W13 paper end'!$L:$L, "0")} -> 0 | R19: {=_xlfn.XLOOKUP($B19, 'W14 paper end'!$C:$C, 'W14 paper end'!$K:$K, "0")} -> 90 | S19: 1 | T19: 92 | U19: 87 | V19: 86 | W19: 1 | AA19: =D19*$D$2+F19*$F$2+H19*$H$2+I19*$I$2+J19*$J$2+L19*$L$2+M19*$M$2+O19*$O$2+P19*$P$2+Q19*$Q$2+R19*$R$2+T19*$T$2+U19*$U$2+V19*$V$2-5*Z19 -> 83.425 | AD19: Lise ZHENG | AE19: =IF(COUNTIF(A:A, AD19)>0, "✓", "") -> ✓ | AF19: 許詠翔 | AG19: =IF(COUNTIF($A:$A, AF19)>0, "✓", "") -> ✓
A20: DENNISON SOEDIBJO | B20: f11415018 | C20: Cyber Si0 | D20: 86 | E20: 1 | F20: 90 | G20: 1 | H20: 100 | I20: 92 | J20: 87 | K20: 1 | L20: 92.5 | M20: {=_xlfn.XLOOKUP($A20, 'Camping Simulation'!$B:$B, 'Camping Simulation'!$K:$K, "X")} -> 91 | N20: 1 | O20: 81 | P20: {=_xlfn.XLOOKUP($B20, 'W12 paper end'!$C:$C, 'W12 paper end'!$L:$L, "0")} -> 90 | Q20: {=_xlfn.XLOOKUP($B20, 'W13 paper end'!$C:$C, 'W13 paper end'!$L:$L, "0")} | R20: {=_xlfn.XLOOKUP($B20, 'W14 paper end'!$C:$C, 'W14 paper end'!$K:$K, "0")} | S20: 1 | T20: 92 | U20: 0 | V20: 0 | W20: 1 | AA20: =D20*$D$2+F20*$F$2+H20*$H$2+I20*$I$2+J20*$J$2+L20*$L$2+M20*$M$2+O20*$O$2+P20*$P$2+Q20*$Q$2+R20*$R$2+T20*$T$2+U20*$U$2+V20*$V$2-5*Z20 -> 76.42 | AD20: Alim Misbullah | AE20: =IF(COUNTIF(A:A, AD20)>0, "✓", "") -> ✓ | AF20: Benjamin Gillard | AG20: =IF(COUNTIF($A:$A, AF20)>0, "✓", "") -> ✓
A21: DIVEN DECHAL JATIPUTRA | B21: f11415019 | C21: Cyber Si0 | D21: 86 | E21: 1 | F21: 90 | G21: 1 | H21: 100 | I21: 92 | J21: 89 | K21: 1 | L21: 92.5 | M21: {=_xlfn.XLOOKUP($A21, 'Camping Simulation'!$B:$B, 'Camping Simulation'!$K:$K, "X")} -> 89 | N21: 1 | O21: 81 | P21: {=_xlfn.XLOOKUP($B21, 'W12 paper end'!$C:$C, 'W12 paper end'!$L:$L, "0")} -> 91 | Q21: {=_xlfn.XLOOKUP($B21, 'W13 paper end'!$C:$C, 'W13 paper end'!$L:$L, "0")} -> 93 | R21: {=_xlfn.XLOOKUP($B21, 'W14 paper end'!$C:$C, 'W14 paper end'!$K:$K, "0")} -> 92 | S21: 1 | T21: 92 | U21: 0 | V21: 92 | W21: 1 | AA21: =D21*$D$2+F21*$F$2+H21*$H$2+I21*$I$2+J21*$J$2+L21*$L$2+M21*$M$2+O21*$O$2+P21*$P$2+Q21*$Q$2+R21*$R$2+T21*$T$2+U21*$U$2+V21*$V$2-5*Z21 -> 88 | AD21: Lindeperg Ugo | AE21: =IF(COUNTIF(A:A, AD21)>0, "✓", "") | AF21: Aurelio Naufal Effendy | AG21: =IF(COUNTIF($A:$A, AF21)>0, "✓", "") -> ✓
A22: JOSHUA PUTRA PRATAMA | B22: f11415027 | C22: Cyber Si0 | D22: 86 | E22: 1 | F22: 90 | G22: 1 | H22: 100 | I22: 92 | J22: 92 | K22: 1 | L22: 92.5 | M22: {=_xlfn.XLOOKUP($A22, 'Camping Simulation'!$B:$B, 'Camping Simulation'!$K:$K, "X")} -> 92 | N22: 1 | O22: 81 | P22: {=_xlfn.XLOOKUP($B22, 'W12 paper end'!$C:$C, 'W12 paper end'!$L:$L, "0")} -> 92 | Q22: {=_xlfn.XLOOKUP($B22, 'W13 paper end'!$C:$C, 'W13 paper end'!$L:$L, "0")} -> 92 | R22: {=_xlfn.XLOOKUP($B22, 'W14 paper end'!$C:$C, 'W14 paper end'!$K:$K, "0")} -> 93 | S22: 1 | T22: 92 | U22: 93 | V22: 93 | W22: 1 | AA22: =D22*$D$2+F22*$F$2+H22*$H$2+I22*$I$2+J22*$J$2+L22*$L$2+M22*$M$2+O22*$O$2+P22*$P$2+Q22*$Q$2+R22*$R$2+T22*$T$2+U22*$U$2+V22*$V$2-5*Z22 -> 90.49 | AD22: Laina Farsiah | AE22: =IF(COUNTIF(A:A, AD22)>0, "✓", "") -> ✓ | AF22: Jules GIRARD | AG22: =IF(COUNTIF($A:$A, AF22)>0, "✓", "") -> ✓
A23: Rivaldo Yudha Pradana | B23: M11407804 | C23: Cyber Si0 | D23: 86 | E23: 1 | F23: 90 | G23: 1 | H23: 100 | I23: 92 | J23: 92 | K23: 1 | L23: 92.5 | M23: {=_xlfn.XLOOKUP($A23, 'Camping Simulation'!$B:$B, 'Camping Simulation'!$K:$K, "X")} -> 91 | N23: 1 | O23: 81 | P23: {=_xlfn.XLOOKUP($B23, 'W12 paper end'!$C:$C, 'W12 paper end'!$L:$L, "0")} -> 93 | Q23: {=_xlfn.XLOOKUP($B23, 'W13 paper end'!$C:$C, 'W13 paper end'!$L:$L, "0")} -> 92 | R23: {=_xlfn.XLOOKUP($B23, 'W14 paper end'!$C:$C, 'W14 paper end'!$K:$K, "0")} -> 93 | S23: 1 | T23: 92 | U23: 93 | V23: 93 | W23: 1 | AA23: =D23*$D$2+F23*$F$2+H23*$H$2+I23*$I$2+J23*$J$2+L23*$L$2+M23*$M$2+O23*$O$2+P23*$P$2+Q23*$Q$2+R23*$R$2+T23*$T$2+U23*$U$2+V23*$V$2-5*Z23 -> 90.52 | AD23: 葉人瑋 | AE23: =IF(COUNTIF(A:A, AD23)>0, "✓", "") -> ✓ | AF23: 盛爾君 | AG23: =IF(COUNTIF($A:$A, AF23)>0, "✓", "") -> ✓
A24: MIKHAEL GERSON SILAEN | B24: m11407809 | C24: Cyber Si0 | D24: 86 | E24: 1 | F24: 90 | G24: 1 | H24: 100 | I24: 92 | J24: 91 | K24: 1 | L24: 92.5 | M24: {=_xlfn.XLOOKUP($A24, 'Camping Simulation'!$B:$B, 'Camping Simulation'!$K:$K, "X")} -> 92 | N24: 1 | O24: 81 | P24: {=_xlfn.XLOOKUP($B24, 'W12 paper end'!$C:$C, 'W12 paper end'!$L:$L, "0")} -> 92 | Q24: {=_xlfn.XLOOKUP($B24, 'W13 paper end'!$C:$C, 'W13 paper end'!$L:$L, "0")} -> 91 | R24: {=_xlfn.XLOOKUP($B24, 'W14 paper end'!$C:$C, 'W14 paper end'!$K:$K, "0")} -> 91 | S24: 1 | T24: 92 | U24: 93 | V24: 93 | W24: 1 | AA24: =D24*$D$2+F24*$F$2+H24*$H$2+I24*$I$2+J24*$J$2+L24*$L$2+M24*$M$2+O24*$O$2+P24*$P$2+Q24*$Q$2+R24*$R$2+T24*$T$2+U24*$U$2+V24*$V$2-5*Z24 -> 90.33 | AD24: Rivaldo Yudha Pradana | AE24: =IF(COUNTIF(A:A, AD24)>0, "✓", "") -> ✓ | AF24: Adam Pach | AG24: =IF(COUNTIF($A:$A, AF24)>0, "✓", "") -> ✓
A25: Peter Jonathan Kuhn | B25: e11415021 | C25: European Avalanche | D25: 90 | E25: 1 | F25: 84 | G25: 1 | H25: 100 | I25: 92 | J25: 92 | K25: 1 | L25: 91 | M25: 0 | N25: 1 | O25: 90 | P25: {=_xlfn.XLOOKUP($B25, 'W12 paper end'!$C:$C, 'W12 paper end'!$L:$L, "0")} -> 89 | Q25: {=_xlfn.XLOOKUP($B25, 'W13 paper end'!$C:$C, 'W13 paper end'!$L:$L, "0")} -> 0 | R25: {=_xlfn.XLOOKUP($B25, 'W14 paper end'!$C:$C, 'W14 paper end'!$K:$K, "0")} -> 88 | S25: 1 | T25: 92 | U25: 91 | V25: 92 | W25: 1 | X25: V | AA25: =D25*$D$2+F25*$F$2+H25*$H$2+I25*$I$2+J25*$J$2+L25*$L$2+M25*$M$2+O25*$O$2+P25*$P$2+Q25*$Q$2+R25*$R$2+T25*$T$2+U25*$U$2+V25*$V$2-5*Z25 -> 84.605 | AD25: Andreas Leeb | AE25: =IF(COUNTIF(A:A, AD25)>0, "✓", "") -> ✓ | AF25: Ugo LINDEPERG | AG25: =IF(COUNTIF($A:$A, AF25)>0, "✓", "")
A26: Ayman Rabih Kallouz | B26: e11415023 | C26: European Avalanche | D26: 90 | E26: 1 | F26: 84 | G26: 1 | H26: 100 | I26: 92 | J26: 88 | K26: 1 | L26: 91 | M26: 0 | N26: 1 | O26: 90 | P26: {=_xlfn.XLOOKUP($B26, 'W12 paper end'!$C:$C, 'W12 paper end'!$L:$L, "0")} -> 89 | Q26: {=_xlfn.XLOOKUP($B26, 'W13 paper end'!$C:$C, 'W13 paper end'!$L:$L, "0")} -> 88 | R26: {=_xlfn.XLOOKUP($B26, 'W14 paper end'!$C:$C, 'W14 paper end'!$K:$K, "0")} -> 90 | S26: 1 | T26: 92 | U26: 92 | V26: 92 | W26: 1 | AA26: =D26*$D$2+F26*$F$2+H26*$H$2+I26*$I$2+J26*$J$2+L26*$L$2+M26*$M$2+O26*$O$2+P26*$P$2+Q26*$Q$2+R26*$R$2+T26*$T$2+U26*$U$2+V26*$V$2-5*Z26 -> 89.09 | AD26: Aurelio Naufal Effendy | AE26: =IF(COUNTIF(A:A, AD26)>0, "✓", "") -> ✓ | AF26: 柯議翔 | AG26: =IF(COUNTIF($A:$A, AF26)>0, "✓", "") -> ✓
A27: Andreas Leeb | B27: e11415025 | C27: European Avalanche | D27: 90 | E27: 1 | F27: 84 | G27: 1 | H27: 100 | I27: 92 | J27: 90 | K27: 1 | L27: 91 | M27: {=_xlfn.XLOOKUP($A27, 'Camping Simulation'!$B:$B, 'Camping Simulation'!$K:$K, "X")} -> 87 | N27: 1 | O27: 90 | P27: {=_xlfn.XLOOKUP($B27, 'W12 paper end'!$C:$C, 'W12 paper end'!$L:$L, "0")} -> 89 | Q27: {=_xlfn.XLOOKUP($B27, 'W13 paper end'!$C:$C, 'W13 paper end'!$L:$L, "0")} -> 87 | R27: {=_xlfn.XLOOKUP($B27, 'W14 paper end'!$C:$C, 'W14 paper end'!$K:$K, "0")} -> 89 | S27: 1 | T27: 92 | U27: 90 | V27: 0 | W27: 1 | AA27: =D27*$D$2+F27*$F$2+H27*$H$2+I27*$I$2+J27*$J$2+L27*$L$2+M27*$M$2+O27*$O$2+P27*$P$2+Q27*$Q$2+R27*$R$2+T27*$T$2+U27*$U$2+V27*$V$2-5*Z27 -> 88.4 | AD27: Danis Putra Perdana | AE27: =IF(COUNTIF(A:A, AD27)>0, "✓", "") -> ✓ | AF27: 張惟凱 | AG27: =IF(COUNTIF($A:$A, AF27)>0, "✓", "") -> ✓
A28: Adam Pach | B28: e11415030 | C28: European Avalanche | D28: 90 | E28: 1 | F28: 84 | G28: 1 | H28: 100 | I28: 92 | J28: 88 | K28: 1 | L28: 91 | M28: {=_xlfn.XLOOKUP($A28, 'Camping Simulation'!$B:$B, 'Camping Simulation'!$K:$K, "X")} -> 89 | N28: 1 | O28: 90 | P28: {=_xlfn.XLOOKUP($B28, 'W12 paper end'!$C:$C, 'W12 paper end'!$L:$L, "0")} -> 90 | Q28: {=_xlfn.XLOOKUP($B28, 'W13 paper end'!$C:$C, 'W13 paper end'!$L:$L, "0")} -> 88 | R28: {=_xlfn.XLOOKUP($B28, 'W14 paper end'!$C:$C, 'W14 paper end'!$K:$K, "0")} -> 92 | S28: 1 | T28: 92 | U28: 0 | V28: 89 | W28: 1 | AA28: =D28*$D$2+F28*$F$2+H28*$H$2+I28*$I$2+J28*$J$2+L28*$L$2+M28*$M$2+O28*$O$2+P28*$P$2+Q28*$Q$2+R28*$R$2+T28*$T$2+U28*$U$2+V28*$V$2-5*Z28 -> 88.645 | AD28: Oriiana Nedzelska | AE28: =IF(COUNTIF(A:A, AD28)>0, "✓", "") -> ✓ | AF28: 吳永保 | AG28: =IF(COUNTIF($A:$A, AF28)>0, "✓", "") -> ✓
A29: Bernardo Cavalcante Vieira de Andrade | B29: e11423008 | C29: European Avalanche | D29: 90 | E29: 1 | F29: 84 | G29: 1 | H29: 100 | I29: 92 | J29: 87 | K29: 1 | L29: 91 | M29: 0 | N29: 1 | O29: 90 | P29: {=_xlfn.XLOOKUP($B29, 'W12 paper end'!$C:$C, 'W12 paper end'!$L:$L, "0")} -> 0 | Q29: {=_xlfn.XLOOKUP($B29, 'W13 paper end'!$C:$C, 'W13 paper end'!$L:$L, "0")} -> 90 | R29: {=_xlfn.XLOOKUP($B29, 'W14 paper end'!$C:$C, 'W14 paper end'!$K:$K, "0")} -> 94 | S29: 1 | T29: 92 | U29: 92 | V29: 0 | W29: 1 | AA29: =D29*$D$2+F29*$F$2+H29*$H$2+I29*$I$2+J29*$J$2+L29*$L$2+M29*$M$2+O29*$O$2+P29*$P$2+Q29*$Q$2+R29*$R$2+T29*$T$2+U29*$U$2+V29*$V$2-5*Z29 -> 82.63 | AD29: 盛爾君 | AE29: =IF(COUNTIF(A:A, AD29)>0, "✓", "") -> ✓ | AF29: 蔡哲維 | AG29: =IF(COUNTIF($A:$A, AF29)>0, "✓", "") -> ✓
A30: Lucas Metzger | B30: f11415020 | C30: European Avalanche | D30: 90 | E30: 1 | F30: 84 | G30: 1 | H30: 100 | I30: 92 | J30: 87 | K30: 1 | L30: 91 | M30: {=_xlfn.XLOOKUP($A30, 'Camping Simulation'!$B:$B, 'Camping Simulation'!$K:$K, "X")} -> 87 | N30: 1 | O30: 90 | P30: {=_xlfn.XLOOKUP($B30, 'W12 paper end'!$C:$C, 'W12 paper end'!$L:$L, "0")} -> 88 | Q30: {=_xlfn.XLOOKUP($B30, 'W13 paper end'!$C:$C, 'W13 paper end'!$L:$L, "0")} -> 88 | R30: {=_xlfn.XLOOKUP(A30, 'W14 paper end'!B:B, 'W14 paper end'!K:K, "X")} -> 87 | S30: 1 | T30: 92 | U30: 90 | V30: 91 | W30: 1 | AA30: =D30*$D$2+F30*$F$2+H30*$H$2+I30*$I$2+J30*$J$2+L30*$L$2+M30*$M$2+O30*$O$2+P30*$P$2+Q30*$Q$2+R30*$R$2+T30*$T$2+U30*$U$2+V30*$V$2-5*Z30 -> 90.545 | AD30: 洪粲鈞 | AE30: =IF(COUNTIF(A:A, AD30)>0, "✓", "") -> ✓ | AF30: Joshua Putra Pratama | AG30: =IF(COUNTIF($A:$A, AF30)>0, "✓", "") -> ✓
A31: ITSUKI KURIYAMA | B31: F11415005 | C31: GPT+ | D31: 83 | E31: 1 | F31: 88 | G31: 1 | H31: 100 | I31: 91 | J31: 0 | K31: 1 | L31: 90 | M31: 0 | N31: 1 | O31: 78 | P31: {=_xlfn.XLOOKUP($B31, 'W12 paper end'!$C:$C, 'W12 paper end'!$L:$L, "0")} -> 94 | Q31: {=_xlfn.XLOOKUP($B31, 'W13 paper end'!$C:$C, 'W13 paper end'!$L:$L, "0")} -> 93 | R31: {=_xlfn.XLOOKUP(A31, 'W14 paper end'!B:B, 'W14 paper end'!K:K, "X")} -> 92 | S31: 1 | T31: 91 | U31: 92 | V31: 92 | W31: 1 | X31: V | AA31: =D31*$D$2+F31*$F$2+H31*$H$2+I31*$I$2+J31*$J$2+L31*$L$2+M31*$M$2+O31*$O$2+P31*$P$2+Q31*$Q$2+R31*$R$2+T31*$T$2+U31*$U$2+V31*$V$2-5*Z31 -> 86.39 | AD31: Joshua Putra Pratama | AE31: =IF(COUNTIF(A:A, AD31)>0, "✓", "") -> ✓ | AF31: Ayman Kallouz | AG31: =IF(COUNTIF($A:$A, AF31)>0, "✓", "")
A32: 祖祥恩 | B32: M11307310 | C32: GPT+ | D32: 83 | E32: 1 | F32: 88 | G32: 1 | H32: 100 | I32: 91 | J32: 85 | K32: 1 | L32: 90 | M32: {=_xlfn.XLOOKUP($A32, 'Camping Simulation'!$B:$B, 'Camping Simulation'!$K:$K, "X")} -> 87 | N32: 1 | O32: 78 | P32: {=_xlfn.XLOOKUP($B32, 'W12 paper end'!$C:$C, 'W12 paper end'!$L:$L, "0")} -> 90 | Q32: {=_xlfn.XLOOKUP($B32, 'W13 paper end'!$C:$C, 'W13 paper end'!$L:$L, "0")} -> 90 | R32: {=_xlfn.XLOOKUP(A32, 'W14 paper end'!B:B, 'W14 paper end'!K:K, "X")} -> 92 | S32: 1 | T32: 91 | U32: 91 | V32: 90 | W32: 1 | AA32: =D32*$D$2+F32*$F$2+H32*$H$2+I32*$I$2+J32*$J$2+L32*$L$2+M32*$M$2+O32*$O$2+P32*$P$2+Q32*$Q$2+R32*$R$2+T32*$T$2+U32*$U$2+V32*$V$2-5*Z32 -> 88.555 | AD32: 黃文良 | AE32: =IF(COUNTIF(A:A, AD32)>0, "✓", "") -> ✓ | AF32: 洪粲鈞 | AG32: =IF(COUNTIF($A:$A, AF32)>0, "✓", "") -> ✓
A33: 葉人瑋 | B33: m11407437 | C33: GPT+ | D33: 83 | E33: 1 | F33: 88 | G33: 1 | H33: 100 | I33: 91 | J33: 85 | K33: 1 | L33: 90 | M33: {=_xlfn.XLOOKUP($A33, 'Camping Simulation'!$B:$B, 'Camping Simulation'!$K:$K, "X")} -> 89 | N33: 1 | O33: 78 | P33: {=_xlfn.XLOOKUP($B33, 'W12 paper end'!$C:$C, 'W12 paper end'!$L:$L, "0")} -> 90 | Q33: {=_xlfn.XLOOKUP($B33, 'W13 paper end'!$C:$C, 'W13 paper end'!$L:$L, "0")} -> 89 | R33: {=_xlfn.XLOOKUP($B33, 'W14 paper end'!$C:$C, 'W14 paper end'!$K:$K, "0")} -> 90 | S33: 1 | T33: 91 | U33: 85 | V33: 0 | W33: 1 | AA33: =D33*$D$2+F33*$F$2+H33*$H$2+I33*$I$2+J33*$J$2+L33*$L$2+M33*$M$2+O33*$O$2+P33*$P$2+Q33*$Q$2+R33*$R$2+T33*$T$2+U33*$U$2+V33*$V$2-5*Z33 -> 86.045 | AD33: 張惟凱 | AE33: =IF(COUNTIF(A:A, AD33)>0, "✓", "") -> ✓ | AF33: Diven Dechal Jatiputra | AG33: =IF(COUNTIF($A:$A, AF33)>0, "✓", "") -> ✓
A34: 蔡哲維 | B34: m11407524 | C34: GPT+ | D34: 83 | E34: 1 | F34: 88 | G34: 1 | H34: 100 | I34: 91 | J34: 0 | K34: 1 | L34: 90 | M34: 0 | N34: 1 | O34: 78 | P34: {=_xlfn.XLOOKUP($B34, 'W12 paper end'!$C:$C, 'W12 paper end'!$L:$L, "0")} -> 90 | Q34: {=_xlfn.XLOOKUP($B34, 'W13 paper end'!$C:$C, 'W13 paper end'!$L:$L, "0")} -> 89 | R34: {=_xlfn.XLOOKUP($B34, 'W14 paper end'!$C:$C, 'W14 paper end'!$K:$K, "0")} -> 90 | S34: 1 | T34: 91 | U34: 0 | V34: 87 | W34: 1 | AA34: =D34*$D$2+F34*$F$2+H34*$H$2+I34*$I$2+J34*$J$2+L34*$L$2+M34*$M$2+O34*$O$2+P34*$P$2+Q34*$Q$2+R34*$R$2+T34*$T$2+U34*$U$2+V34*$V$2-5*Z34 -> 83.465 | AD34: 胡承學 | AE34: =IF(COUNTIF(A:A, AD34)>0, "✓", "") -> ✓ | AF34: 黃文良 | AG34: =IF(COUNTIF($A:$A, AF34)>0, "✓", "") -> ✓
A35: 陳增勇 | B35: B11007106 | C35: Insect | D35: 92 | E35: 1 | F35: 94 | G35: 1 | H35: 100 | I35: 95 | J35: 88 | K35: 1 | L35: 83 | M35: {=_xlfn.XLOOKUP($A35, 'Camping Simulation'!$B:$B, 'Camping Simulation'!$K:$K, "X")} -> 92 | N35: 1 | O35: 82 | P35: {=_xlfn.XLOOKUP($B35, 'W12 paper end'!$C:$C, 'W12 paper end'!$L:$L, "0")} -> 0 | Q35: {=_xlfn.XLOOKUP($B35, 'W13 paper end'!$C:$C, 'W13 paper end'!$L:$L, "0")} -> 91 | R35: {=_xlfn.XLOOKUP($B35, 'W14 paper end'!$C:$C, 'W14 paper end'!$K:$K, "0")} -> 90 | S35: 1 | T35: 95 | U35: 93 | V35: 92 | W35: 1 | AA35: =D35*$D$2+F35*$F$2+H35*$H$2+I35*$I$2+J35*$J$2+L35*$L$2+M35*$M$2+O35*$O$2+P35*$P$2+Q35*$Q$2+R35*$R$2+T35*$T$2+U35*$U$2+V35*$V$2-5*Z35 -> 86.735 | AD35: Dennison Soedibjo | AE35: =IF(COUNTIF(A:A, AD35)>0, "✓", "") -> ✓ | AF35: 楊晴安 | AG35: =IF(COUNTIF($A:$A, AF35)>0, "✓", "") -> ✓
A36: Laina Farsiah | B36: D11415802 | C36: Insect | D36: 92 | E36: 1 | F36: 94 | G36: 1 | H36: 100 | I36: 95 | J36: 95 | K36: 1 | L36: 83 | M36: {=_xlfn.XLOOKUP($A36, 'Camping Simulation'!$B:$B, 'Camping Simulation'!$K:$K, "X")} -> 94 | N36: 1 | O36: 82 | P36: {=_xlfn.XLOOKUP($B36, 'W12 paper end'!$C:$C, 'W12 paper end'!$L:$L, "0")} -> 92 | Q36: {=_xlfn.XLOOKUP($B36, 'W13 paper end'!$C:$C, 'W13 paper end'!$L:$L, "0")} -> 92 | R36: {=_xlfn.XLOOKUP($B36, 'W14 paper end'!$C:$C, 'W14 paper end'!$K:$K, "0")} -> 95 | S36: 1 | T36: 95 | U36: 94 | V36: 94 | W36: 1 | X36: V | AA36: =D36*$D$2+F36*$F$2+H36*$H$2+I36*$I$2+J36*$J$2+L36*$L$2+M36*$M$2+O36*$O$2+P36*$P$2+Q36*$Q$2+R36*$R$2+T36*$T$2+U36*$U$2+V36*$V$2-5*Z36 -> 91.82 | AD36: 吳永保 | AE36: =IF(COUNTIF(A:A, AD36)>0, "✓", "") -> ✓ | AF36: Bernardo Andrade | AG36: =IF(COUNTIF($A:$A, AF36)>0, "✓", "")
A37: Alim Misbullah | B37: D11415803 | C37: Insect | D37: 92 | E37: 1 | F37: 94 | G37: 1 | H37: 100 | I37: 95 | J37: 90 | K37: 1 | L37: 83 | M37: {=_xlfn.XLOOKUP($A37, 'Camping Simulation'!$B:$B, 'Camping Simulation'!$K:$K, "X")} -> 93 | N37: 1 | O37: 82 | P37: {=_xlfn.XLOOKUP($B37, 'W12 paper end'!$C:$C, 'W12 paper end'!$L:$L, "0")} -> 92 | Q37: {=_xlfn.XLOOKUP($B37, 'W13 paper end'!$C:$C, 'W13 paper end'!$L:$L, "0")} -> 90 | R37: {=_xlfn.XLOOKUP($B37, 'W14 paper end'!$C:$C, 'W14 paper end'!$K:$K, "0")} -> 91 | S37: 1 | T37: 95 | U37: 91 | V37: 93 | W37: 1 | X37: V | AA37: =D37*$D$2+F37*$F$2+H37*$H$2+I37*$I$2+J37*$J$2+L37*$L$2+M37*$M$2+O37*$O$2+P37*$P$2+Q37*$Q$2+R37*$R$2+T37*$T$2+U37*$U$2+V37*$V$2-5*Z37 -> 91.35 | AD37: 楊晴安 | AE37: =IF(COUNTIF(A:A, AD37)>0, "✓", "") -> ✓ | AF37: 胡承學 | AG37: =IF(COUNTIF($A:$A, AF37)>0, "✓", "") -> ✓
A38: Danis Putra Perdana | B38: D11415806 | C38: Insect | D38: 92 | E38: 1 | F38: 94 | G38: 1 | H38: 100 | I38: 95 | J38: 90 | K38: 1 | L38: 83 | M38: {=_xlfn.XLOOKUP($A38, 'Camping Simulation'!$B:$B, 'Camping Simulation'!$K:$K, "X")} -> 89 | N38: 1 | O38: 82 | P38: {=_xlfn.XLOOKUP($B38, 'W12 paper end'!$C:$C, 'W12 paper end'!$L:$L, "0")} -> 90 | Q38: {=_xlfn.XLOOKUP($B38, 'W13 paper end'!$C:$C, 'W13 paper end'!$L:$L, "0")} -> 91 | R38: {=_xlfn.XLOOKUP($B38, 'W14 paper end'!$C:$C, 'W14 paper end'!$K:$K, "0")} -> 90 | S38: 1 | T38: 95 | U38: 88 | V38: 89 | W38: 1 | X38: V | AA38: =D38*$D$2+F38*$F$2+H38*$H$2+I38*$I$2+J38*$J$2+L38*$L$2+M38*$M$2+O38*$O$2+P38*$P$2+Q38*$Q$2+R38*$R$2+T38*$T$2+U38*$U$2+V38*$V$2-5*Z38 -> 90.995 | AD38: Ituski Kuriyama | AE38: =IF(COUNTIF(A:A, AD38)>0, "✓", "") | AF38: Itsuki Kuriyama | AG38: =IF(COUNTIF($A:$A, AF38)>0, "✓", "") -> ✓
A39: Puspa Ira Dewi Candra Wulan | B39: D11415807 | C39: Insect | D39: 92 | E39: 1 | F39: 94 | G39: 1 | H39: 100 | I39: 95 | J39: 88 | K39: 1 | L39: 83 | M39: {=_xlfn.XLOOKUP($A39, 'Camping Simulation'!$B:$B, 'Camping Simulation'!$K:$K, "X")} -> 90 | N39: 1 | O39: 82 | P39: {=_xlfn.XLOOKUP($B39, 'W12 paper end'!$C:$C, 'W12 paper end'!$L:$L, "X")} -> 93 | Q39: {=_xlfn.XLOOKUP($B39, 'W13 paper end'!$C:$C, 'W13 paper end'!$L:$L, "0")} -> 91 | R39: {=_xlfn.XLOOKUP($B39, 'W14 paper end'!$C:$C, 'W14 paper end'!$K:$K, "0")} -> 89 | S39: 1 | T39: 95 | U39: 93 | V39: 91 | W39: 1 | X39: V | Y39: V | AA39: =D39*$D$2+F39*$F$2+H39*$H$2+I39*$I$2+J39*$J$2+L39*$L$2+M39*$M$2+O39*$O$2+P39*$P$2+Q39*$Q$2+R39*$R$2+T39*$T$2+U39*$U$2+V39*$V$2-5*Z39 -> 91.27
A40: Aurelio Naufal Effendy | B40: M11415802 | C40: Insect | D40: 92 | E40: 1 | F40: 94 | G40: 1 | H40: 100 | I40: 95 | J40: 90 | K40: 1 | L40: 83 | M40: {=_xlfn.XLOOKUP($A40, 'Camping Simulation'!$B:$B, 'Camping Simulation'!$K:$K, "X")} -> 95 | N40: 1 | O40: 82 | P40: {=_xlfn.XLOOKUP($B40, 'W12 paper end'!$C:$C, 'W12 paper end'!$L:$L, "X")} -> 92 | Q40: {=_xlfn.XLOOKUP($B40, 'W13 paper end'!$C:$C, 'W13 paper end'!$L:$L, "0")} -> 92 | R40: {=_xlfn.XLOOKUP($B40, 'W14 paper end'!$C:$C, 'W14 paper end'!$K:$K, "0")} -> 92 | S40: 1 | T40: 95 | U40: 90 | V40: 92 | W40: 1 | AA40: =D40*$D$2+F40*$F$2+H40*$H$2+I40*$I$2+J40*$J$2+L40*$L$2+M40*$M$2+O40*$O$2+P40*$P$2+Q40*$Q$2+R40*$R$2+T40*$T$2+U40*$U$2+V40*$V$2-5*Z40 -> 91.49
...

Sheet Professor ratings
A1: News Groups | B1: News(CTI report) | C1: News 成績 | D1: Cuckoo 順序 | E1: Cuckoo 成績 | F1: Cuckoo 有人沒到 | G1: Campaign | H1: Paper Presentation | I1: Paper Presentation 成績 | J1: Term Project
A2: beni | B2: SolarStorm Supply Chain Attack Timeline | C2: 90 | D2: beni (emotet) | E2: 84 | G2: 91 | H2: POIROT: Aligning Attack Behavior with Kernel Audit Records for Cyber Threat Hunting | I2: 85 | J2: 95
A3: European avalanche | B3: Taming Agentic Browsers: Vulnerability in Chrome Allowed Extensions to Hijack New Gemini Panel | C3: 90 | D3: European avalanche | E3: 84 | G3: 91 | H3: PalmTree: Learning an Assembly Language Model for Instruction Embedding | I3: 90 | J3: 92
A4: Cybersix | B4: Threat Assessment: BlackCat Ransomware | C4: 86 | D4: Cybersix (Agent Tesla) | E4: 90 | G4: 92.5 | H4: HOLMES: Real-Time APT Detection through Correlation of Suspicious Information Flows | I4: 81 | J4: 92
A5: insect | B5: LANDFALL: New Commercial-Grade Android Spyware in Exploit Chain Targeting Samsung Devices | C5: 92 | D5: insect | E5: 94 | G5: 83 | H5: You Are What You Do: Hunting Stealthy Malware via Data Provenance Analysis | I5: 82 | J5: 95
A6: ANTSLAB | B6: Fooling AI Agents: Web-Based Indirect Prompt Injection Observed in the Wild | C6: 86 | D6: ANTSLAB | E6: 94 | F6: 1位未到(黃文良) --> 報告者要到，否則會扣分唷，請他來跟我請假 (我沒有收到請假，所以扣5分唷) | G6: 93 | H6: SoK: Automated TTP Extraction from CTI Reports – Are We There Yet? | I6: 94 | J6: 95
A7: GPT+ | B7: Hack the Real Box: APT41’s New Subgroup Earth Longzhi | C7: 83 | D7: GPT+ | E7: 88 | F7: 1位請假(ITSUKI KURIYAMA) | G7: 90 | H7: Formalizing and Benchmarking Prompt Injection Attacks and Defenses | I7: 78 | J7: 91
A8: cyberpunk | B8: Model Namespace Reuse: An AI Supply-Chain Attack Exploiting Model Name Trust | C8: 83 | D8: cyberpunk (Agent Tesla) | E8: 90 | G8: 92 | H8: A Framework for Formalizing LLM Agent Security | I8: 88 | J8: 92

Sheet Cybersec
A1: 名字 | B1: 學號 | C1: 電子郵件信箱 | D1: 分組 | E1: Cybersec 2026 心得 | F1: B | G1: LLM
A2: 黃文良 | B2: B11107152 | C2: a0930747852@gmail.com | D2: ANTSLAB | E2: {=IF(ISNA(_xlfn.XLOOKUP(B2, H:H, H:H)), "", "✔")} | F2: =IF(ISNA(_xlfn.XLOOKUP(B2, H:H, H:H)), "", "✔")
A3: 胡承學 | B3: B11107153 | C3: B11107153@mail.ntust.edu.tw | D3: ANTSLAB | F3: =IF(ISNA(_xlfn.XLOOKUP(B3, H:H, H:H)), "", "✔")
A4: 吳永保 | B4: M11407005 | C4: M11407005@mail.ntust.edu.tw | D4: ANTSLAB | F4: =IF(ISNA(_xlfn.XLOOKUP(B4, H:H, H:H)), "", "✔")
A5: 楊晴安 | B5: M11407507 | C5: M11407507@mail.ntust.edu.tw | D5: ANTSLAB | E5: V | F5: =IF(ISNA(_xlfn.XLOOKUP(B5, H:H, H:H)), "", "✔")
A6: 洪粲鈞 | B6: M11407519 | C6: M11407519@mail.ntust.edu.tw | D6: ANTSLAB | E6: V | F6: =IF(ISNA(_xlfn.XLOOKUP(B6, H:H, H:H)), "", "✔")
A7: 張惟凱 | B7: M11407522 | C7: M11407522@mail.ntust.edu.tw | D7: ANTSLAB | E7: V | F7: =IF(ISNA(_xlfn.XLOOKUP(B7, H:H, H:H)), "", "✔")
A8: SU YADANA WIN | B8: d11415809 | C8: D11415809@mail.ntust.edu.tw | D8: BENI | E8: V | F8: =IF(ISNA(_xlfn.XLOOKUP(B8, H:H, H:H)), "", "✔")
A9: Jules GIRARD | B9: e11415022 | C9: jules.girard@etu.uca.fr | D9: BENI | F9: =IF(ISNA(_xlfn.XLOOKUP(B9, H:H, H:H)), "", "✔")
A10: Benjamin GILLARD | B10: e11415026 | C10: Benjamin.GILLARD@etu.uca.fr | D10: BENI | F10: =IF(ISNA(_xlfn.XLOOKUP(B10, H:H, H:H)), "", "✔")
A11: Ugo LINDEPERG | B11: e11415027 | C11: Ugo.LINDEPERG@etu.uca.fr | D11: BENI | F11: =IF(ISNA(_xlfn.XLOOKUP(B11, H:H, H:H)), "", "✔")
A12: Oriiana Nedzelska | B12: f11415026 | C12: oriiana.nedzelska@stud.hslu.ch | D12: BENI | E12: V | F12: =IF(ISNA(_xlfn.XLOOKUP(B12, H:H, H:H)), "", "✔") | G12: V
A13: Lise ZHENG | B13: f11402009 | C13: lise.zheng@etu.cyu.fr | D13: Cyber Punk | F13: =IF(ISNA(_xlfn.XLOOKUP(B13, H:H, H:H)), "", "✔")
A14: 柯議翔 | B14: M11407319 | C14: M11407319@mail.ntust.edu.tw | D14: Cyber Punk | F14: =IF(ISNA(_xlfn.XLOOKUP(B14, H:H, H:H)), "", "✔")
A15: 盛爾君 | B15: M11407501 | C15: M11407501@mail.ntust.edu.tw | D15: Cyber Punk | F15: =IF(ISNA(_xlfn.XLOOKUP(B15, H:H, H:H)), "", "✔")
A16: 許詠翔 | B16: M11407502 | C16: M11407502@mail.ntust.edu.tw | D16: Cyber Punk | F16: =IF(ISNA(_xlfn.XLOOKUP(B16, H:H, H:H)), "", "✔")
A17: 龔效諄 | B17: M11407618 | C17: M11407618@mail.ntust.edu.tw | D17: Cyber Punk | E17: V | F17: =IF(ISNA(_xlfn.XLOOKUP(B17, H:H, H:H)), "", "✔")
A18: Walfroy, Yves, Francois, SAINT-GUILHEM | B18: e11415031 | C18: walfroy.saint_guilhem@utt.fr | D18: Cyber Six | F18: =IF(ISNA(_xlfn.XLOOKUP(B18, H:H, H:H)), "", "✔")
A19: DENNISON SOEDIBJO | B19: f11415018 | C19: dennison.soedibjo@binus.ac.id | D19: Cyber Six | F19: =IF(ISNA(_xlfn.XLOOKUP(B19, H:H, H:H)), "", "✔")
A20: DIVEN DECHAL JATIPUTRA | B20: f11415019 | C20: diven.jatiputra@binus.ac.id | D20: Cyber Six | F20: =IF(ISNA(_xlfn.XLOOKUP(B20, H:H, H:H)), "", "✔")
A21: JOSHUA PUTRA PRATAMA | B21: f11415027 | C21: joshua.pratama@binus.ac.id | D21: Cyber Six | F21: =IF(ISNA(_xlfn.XLOOKUP(B21, H:H, H:H)), "", "✔")
A22: Rivaldo Yudha Pradana | B22: M11407804 | C22: M11407804@mail.ntust.edu.tw | D22: Cyber Six | F22: =IF(ISNA(_xlfn.XLOOKUP(B22, H:H, H:H)), "", "✔")
A23: MIKHAEL GERSON SILAEN | B23: m11407809 | C23: M11407809@mail.ntust.edu.tw | D23: Cyber Six | F23: =IF(ISNA(_xlfn.XLOOKUP(B23, H:H, H:H)), "", "✔")
A24: Peter Jonathan Kuhn | B24: e11415021 | C24: peter.kuhn@ost.ch | D24: European Avalanche | E24: V | F24: =IF(ISNA(_xlfn.XLOOKUP(B24, H:H, H:H)), "", "✔")
A25: Ayman Rabih Kallouz | B25: e11415023 | C25: ayman.kallouz@stud.tu-darmstadt.de | D25: European Avalanche | F25: =IF(ISNA(_xlfn.XLOOKUP(B25, H:H, H:H)), "", "✔")
A26: Andreas Leeb | B26: e11415025 | C26: k12215901@students.jku.at | D26: European Avalanche | F26: =IF(ISNA(_xlfn.XLOOKUP(B26, H:H, H:H)), "", "✔")
